Workbook

Sheet 🗂 Ichiran
B2: 🗂 ICHIRAN — PAINEL DE CONTROLE CENTRAL
B3: Mês base = Mês de Referência do Dashboard | 🔵 Fundo azul = você digita (PREVISTO) | Texto azul = automático das Movimentações
B5: 📅 Coluna D = mês do Dashboard | E-I = meses seguintes | Altere o mês no Dashboard (aba 📊) para navegar | 🔵 Azul escuro = digite aqui | Texto azul = automático
B6: ITEM | C6: TIPO | D6: =TEXT(DATE(YEAR($D$200)+INT((MONTH($D$200)+0-1)/12),MOD(MONTH($D$200)+0-1,12)+1,1),"MMM/YY") -> May/25 | E6: =TEXT(DATE(YEAR($D$200)+INT((MONTH($D$200)+1-1)/12),MOD(MONTH($D$200)+1-1,12)+1,1),"MMM/YY") -> Jun/25 | F6: =TEXT(DATE(YEAR($D$200)+INT((MONTH($D$200)+2-1)/12),MOD(MONTH($D$200)+2-1,12)+1,1),"MMM/YY") -> Jul/25 | G6: =TEXT(DATE(YEAR($D$200)+INT((MONTH($D$200)+3-1)/12),MOD(MONTH($D$200)+3-1,12)+1,1),"MMM/YY") -> Aug/25 | H6: =TEXT(DATE(YEAR($D$200)+INT((MONTH($D$200)+4-1)/12),MOD(MONTH($D$200)+4-1,12)+1,1),"MMM/YY") -> Sep/25 | I6: =TEXT(DATE(YEAR($D$200)+INT((MONTH($D$200)+5-1)/12),MOD(MONTH($D$200)+5-1,12)+1,1),"MMM/YY") -> Oct/25 | J6: TOTAL ANO
B8: ▲ RENDA
B9: Salário | C9: PREV | D9: 374000 | E9: 0 | F9: 0 | G9: 0 | H9: 0 | I9: 0 | J9: =SUM(D9,E9,F9,G9,H9,I9) -> 374000
C10: REAL | D10: =IFERROR(SUMIFS('📋 Movimentações'!$F$15:$F$514,'📋 Movimentações'!$B$15:$B$514,">="&DATE(YEAR($D$200)+INT((MONTH($D$200)+0-1)/12),MOD(MONTH($D$200)+0-1,12)+1,1),'📋 Movimentações'!$B$15:$B$514,"<="&EOMONTH(DATE(YEAR($D$200)+INT((MONTH($D$200)+0-1)/12),MOD(MONTH($D$200)+0-1,12)+1,1),0),'📋 Movimentações'!$E$15:$E$514,"Entrada",'📋 Movimentações'!$D$15:$D$514,"Salário"),0) -> 374000 | E10: =IFERROR(SUMIFS('📋 Movimentações'!$F$15:$F$514,'📋 Movimentações'!$B$15:$B$514,">="&DATE(YEAR($D$200)+INT((MONTH($D$200)+1-1)/12),MOD(MONTH($D$200)+1-1,12)+1,1),'📋 Movimentações'!$B$15:$B$514,"<="&EOMONTH(DATE(YEAR($D$200)+INT((MONTH($D$200)+1-1)/12),MOD(MONTH($D$200)+1-1,12)+1,1),0),'📋 Movimentações'!$E$15:$E$514,"Entrada",'📋 Movimentações'!$D$15:$D$514,"Salário"),0) -> 0 | F10: =IFERROR(SUMIFS('📋 Movimentações'!$F$15:$F$514,'📋 Movimentações'!$B$15:$B$514,">="&DATE(YEAR($D$200)+INT((MONTH($D$200)+2-1)/12),MOD(MONTH($D$200)+2-1,12)+1,1),'📋 Movimentações'!$B$15:$B$514,"<="&EOMONTH(DATE(YEAR($D$200)+INT((MONTH($D$200)+2-1)/12),MOD(MONTH($D$200)+2-1,12)+1,1),0),'📋 Movimentações'!$E$15:$E$514,"Entrada",'📋 Movimentações'!$D$15:$D$514,"Salário"),0) -> 0 | G10: =IFERROR(SUMIFS('📋 Movimentações'!$F$15:$F$514,'📋 Movimentações'!$B$15:$B$514,">="&DATE(YEAR($D$200)+INT((MONTH($D$200)+3-1)/12),MOD(MONTH($D$200)+3-1,12)+1,1),'📋 Movimentações'!$B$15:$B$514,"<="&EOMONTH(DATE(YEAR($D$200)+INT((MONTH($D$200)+3-1)/12),MOD(MONTH($D$200)+3-1,12)+1,1),0),'📋 Movimentações'!$E$15:$E$514,"Entrada",'📋 Movimentações'!$D$15:$D$514,"Salário"),0) -> 0 | H10: =IFERROR(SUMIFS('📋 Movimentações'!$F$15:$F$514,'📋 Movimentações'!$B$15:$B$514,">="&DATE(YEAR($D$200)+INT((MONTH($D$200)+4-1)/12),MOD(MONTH($D$200)+4-1,12)+1,1),'📋 Movimentações'!$B$15:$B$514,"<="&EOMONTH(DATE(YEAR($D$200)+INT((MONTH($D$200)+4-1)/12),MOD(MONTH($D$200)+4-1,12)+1,1),0),'📋 Movimentações'!$E$15:$E$514,"Entrada",'📋 Movimentações'!$D$15:$D$514,"Salário"),0) -> 0 | I10: =IFERROR(SUMIFS('📋 Movimentações'!$F$15:$F$514,'📋 Movimentações'!$B$15:$B$514,">="&DATE(YEAR($D$200)+INT((MONTH($D$200)+5-1)/12),MOD(MONTH($D$200)+5-1,12)+1,1),'📋 Movimentações'!$B$15:$B$514,"<="&EOMONTH(DATE(YEAR($D$200)+INT((MONTH($D$200)+5-1)/12),MOD(MONTH($D$200)+5-1,12)+1,1),0),'📋 Movimentações'!$E$15:$E$514,"Entrada",'📋 Movimentações'!$D$15:$D$514,"Salário"),0) -> 0 | J10: =SUM(D10,E10,F10,G10,H10,I10) -> 374000
B11: Hora Extra | C11: PREV | D11: 20000 | E11: 0 | F11: 0 | G11: 0 | H11: 0 | I11: 0 | J11: =SUM(D11,E11,F11,G11,H11,I11) -> 20000
C12: REAL | D12: =IFERROR(SUMIFS('📋 Movimentações'!$F$15:$F$514,'📋 Movimentações'!$B$15:$B$514,">="&DATE(YEAR($D$200)+INT((MONTH($D$200)+0-1)/12),MOD(MONTH($D$200)+0-1,12)+1,1),'📋 Movimentações'!$B$15:$B$514,"<="&EOMONTH(DATE(YEAR($D$200)+INT((MONTH($D$200)+0-1)/12),MOD(MONTH($D$200)+0-1,12)+1,1),0),'📋 Movimentações'!$E$15:$E$514,"Entrada",'📋 Movimentações'!$D$15:$D$514,"Hora Extra"),0) -> 0 | E12: =IFERROR(SUMIFS('📋 Movimentações'!$F$15:$F$514,'📋 Movimentações'!$B$15:$B$514,">="&DATE(YEAR($D$200)+INT((MONTH($D$200)+1-1)/12),MOD(MONTH($D$200)+1-1,12)+1,1),'📋 Movimentações'!$B$15:$B$514,"<="&EOMONTH(DATE(YEAR($D$200)+INT((MONTH($D$200)+1-1)/12),MOD(MONTH($D$200)+1-1,12)+1,1),0),'📋 Movimentações'!$E$15:$E$514,"Entrada",'📋 Movimentações'!$D$15:$D$514,"Hora Extra"),0) -> 0 | F12: =IFERROR(SUMIFS('📋 Movimentações'!$F$15:$F$514,'📋 Movimentações'!$B$15:$B$514,">="&DATE(YEAR($D$200)+INT((MONTH($D$200)+2-1)/12),MOD(MONTH($D$200)+2-1,12)+1,1),'📋 Movimentações'!$B$15:$B$514,"<="&EOMONTH(DATE(YEAR($D$200)+INT((MONTH($D$200)+2-1)/12),MOD(MONTH($D$200)+2-1,12)+1,1),0),'📋 Movimentações'!$E$15:$E$514,"Entrada",'📋 Movimentações'!$D$15:$D$514,"Hora Extra"),0) -> 0 | G12: =IFERROR(SUMIFS('📋 Movimentações'!$F$15:$F$514,'📋 Movimentações'!$B$15:$B$514,">="&DATE(YEAR($D$200)+INT((MONTH($D$200)+3-1)/12),MOD(MONTH($D$200)+3-1,12)+1,1),'📋 Movimentações'!$B$15:$B$514,"<="&EOMONTH(DATE(YEAR($D$200)+INT((MONTH($D$200)+3-1)/12),MOD(MONTH($D$200)+3-1,12)+1,1),0),'📋 Movimentações'!$E$15:$E$514,"Entrada",'📋 Movimentações'!$D$15:$D$514,"Hora Extra"),0) -> 0 | H12: =IFERROR(SUMIFS('📋 Movimentações'!$F$15:$F$514,'📋 Movimentações'!$B$15:$B$514,">="&DATE(YEAR($D$200)+INT((MONTH($D$200)+4-1)/12),MOD(MONTH($D$200)+4-1,12)+1,1),'📋 Movimentações'!$B$15:$B$514,"<="&EOMONTH(DATE(YEAR($D$200)+INT((MONTH($D$200)+4-1)/12),MOD(MONTH($D$200)+4-1,12)+1,1),0),'📋 Movimentações'!$E$15:$E$514,"Entrada",'📋 Movimentações'!$D$15:$D$514,"Hora Extra"),0) -> 0 | I12: =IFERROR(SUMIFS('📋 Movimentações'!$F$15:$F$514,'📋 Movimentações'!$B$15:$B$514,">="&DATE(YEAR($D$200)+INT((MONTH($D$200)+5-1)/12),MOD(MONTH($D$200)+5-1,12)+1,1),'📋 Movimentações'!$B$15:$B$514,"<="&EOMONTH(DATE(YEAR($D$200)+INT((MONTH($D$200)+5-1)/12),MOD(MONTH($D$200)+5-1,12)+1,1),0),'📋 Movimentações'!$E$15:$E$514,"Entrada",'📋 Movimentações'!$D$15:$D$514,"Hora Extra"),0) -> 0 | J12: =SUM(D12,E12,F12,G12,H12,I12) -> 0
B13: Bônus | C13: PREV | D13: 0 | E13: 0 | F13: 0 | G13: 0 | H13: 0 | I13: 0 | J13: =SUM(D13,E13,F13,G13,H13,I13) -> 0
C14: REAL | D14: =IFERROR(SUMIFS('📋 Movimentações'!$F$15:$F$514,'📋 Movimentações'!$B$15:$B$514,">="&DATE(YEAR($D$200)+INT((MONTH($D$200)+0-1)/12),MOD(MONTH($D$200)+0-1,12)+1,1),'📋 Movimentações'!$B$15:$B$514,"<="&EOMONTH(DATE(YEAR($D$200)+INT((MONTH($D$200)+0-1)/12),MOD(MONTH($D$200)+0-1,12)+1,1),0),'📋 Movimentações'!$E$15:$E$514,"Entrada",'📋 Movimentações'!$D$15:$D$514,"Bônus"),0) -> 55000 | E14: =IFERROR(SUMIFS('📋 Movimentações'!$F$15:$F$514,'📋 Movimentações'!$B$15:$B$514,">="&DATE(YEAR($D$200)+INT((MONTH($D$200)+1-1)/12),MOD(MONTH($D$200)+1-1,12)+1,1),'📋 Movimentações'!$B$15:$B$514,"<="&EOMONTH(DATE(YEAR($D$200)+INT((MONTH($D$200)+1-1)/12),MOD(MONTH($D$200)+1-1,12)+1,1),0),'📋 Movimentações'!$E$15:$E$514,"Entrada",'📋 Movimentações'!$D$15:$D$514,"Bônus"),0) -> 0 | F14: =IFERROR(SUMIFS('📋 Movimentações'!$F$15:$F$514,'📋 Movimentações'!$B$15:$B$514,">="&DATE(YEAR($D$200)+INT((MONTH($D$200)+2-1)/12),MOD(MONTH($D$200)+2-1,12)+1,1),'📋 Movimentações'!$B$15:$B$514,"<="&EOMONTH(DATE(YEAR($D$200)+INT((MONTH($D$200)+2-1)/12),MOD(MONTH($D$200)+2-1,12)+1,1),0),'📋 Movimentações'!$E$15:$E$514,"Entrada",'📋 Movimentações'!$D$15:$D$514,"Bônus"),0) -> 0 | G14: =IFERROR(SUMIFS('📋 Movimentações'!$F$15:$F$514,'📋 Movimentações'!$B$15:$B$514,">="&DATE(YEAR($D$200)+INT((MONTH($D$200)+3-1)/12),MOD(MONTH($D$200)+3-1,12)+1,1),'📋 Movimentações'!$B$15:$B$514,"<="&EOMONTH(DATE(YEAR($D$200)+INT((MONTH($D$200)+3-1)/12),MOD(MONTH($D$200)+3-1,12)+1,1),0),'📋 Movimentações'!$E$15:$E$514,"Entrada",'📋 Movimentações'!$D$15:$D$514,"Bônus"),0) -> 0 | H14: =IFERROR(SUMIFS('📋 Movimentações'!$F$15:$F$514,'📋 Movimentações'!$B$15:$B$514,">="&DATE(YEAR($D$200)+INT((MONTH($D$200)+4-1)/12),MOD(MONTH($D$200)+4-1,12)+1,1),'📋 Movimentações'!$B$15:$B$514,"<="&EOMONTH(DATE(YEAR($D$200)+INT((MONTH($D$200)+4-1)/12),MOD(MONTH($D$200)+4-1,12)+1,1),0),'📋 Movimentações'!$E$15:$E$514,"Entrada",'📋 Movimentações'!$D$15:$D$514,"Bônus"),0) -> 0 | I14: =IFERROR(SUMIFS('📋 Movimentações'!$F$15:$F$514,'📋 Movimentações'!$B$15:$B$514,">="&DATE(YEAR($D$200)+INT((MONTH($D$200)+5-1)/12),MOD(MONTH($D$200)+5-1,12)+1,1),'📋 Movimentações'!$B$15:$B$514,"<="&EOMONTH(DATE(YEAR($D$200)+INT((MONTH($D$200)+5-1)/12),MOD(MONTH($D$200)+5-1,12)+1,1),0),'📋 Movimentações'!$E$15:$E$514,"Entrada",'📋 Movimentações'!$D$15:$D$514,"Bônus"),0) -> 0 | J14: =SUM(D14,E14,F14,G14,H14,I14) -> 55000
B15: Arubaito / Extra | C15: PREV | D15: 0 | E15: 0 | F15: 0 | G15: 0 | H15: 0 | I15: 0 | J15: =SUM(D15,E15,F15,G15,H15,I15) -> 0
C16: REAL | D16: =IFERROR(SUMIFS('📋 Movimentações'!$F$15:$F$514,'📋 Movimentações'!$B$15:$B$514,">="&DATE(YEAR($D$200)+INT((MONTH($D$200)+0-1)/12),MOD(MONTH($D$200)+0-1,12)+1,1),'📋 Movimentações'!$B$15:$B$514,"<="&EOMONTH(DATE(YEAR($D$200)+INT((MONTH($D$200)+0-1)/12),MOD(MONTH($D$200)+0-1,12)+1,1),0),'📋 Movimentações'!$E$15:$E$514,"Entrada",'📋 Movimentações'!$D$15:$D$514,"Arubaito/Extra"),0) -> 0 | E16: =IFERROR(SUMIFS('📋 Movimentações'!$F$15:$F$514,'📋 Movimentações'!$B$15:$B$514,">="&DATE(YEAR($D$200)+INT((MONTH($D$200)+1-1)/12),MOD(MONTH($D$200)+1-1,12)+1,1),'📋 Movimentações'!$B$15:$B$514,"<="&EOMONTH(DATE(YEAR($D$200)+INT((MONTH($D$200)+1-1)/12),MOD(MONTH($D$200)+1-1,12)+1,1),0),'📋 Movimentações'!$E$15:$E$514,"Entrada",'📋 Movimentações'!$D$15:$D$514,"Arubaito/Extra"),0) -> 0 | F16: =IFERROR(SUMIFS('📋 Movimentações'!$F$15:$F$514,'📋 Movimentações'!$B$15:$B$514,">="&DATE(YEAR($D$200)+INT((MONTH($D$200)+2-1)/12),MOD(MONTH($D$200)+2-1,12)+1,1),'📋 Movimentações'!$B$15:$B$514,"<="&EOMONTH(DATE(YEAR($D$200)+INT((MONTH($D$200)+2-1)/12),MOD(MONTH($D$200)+2-1,12)+1,1),0),'📋 Movimentações'!$E$15:$E$514,"Entrada",'📋 Movimentações'!$D$15:$D$514,"Arubaito/Extra"),0) -> 0 | G16: =IFERROR(SUMIFS('📋 Movimentações'!$F$15:$F$514,'📋 Movimentações'!$B$15:$B$514,">="&DATE(YEAR($D$200)+INT((MONTH($D$200)+3-1)/12),MOD(MONTH($D$200)+3-1,12)+1,1),'📋 Movimentações'!$B$15:$B$514,"<="&EOMONTH(DATE(YEAR($D$200)+INT((MONTH($D$200)+3-1)/12),MOD(MONTH($D$200)+3-1,12)+1,1),0),'📋 Movimentações'!$E$15:$E$514,"Entrada",'📋 Movimentações'!$D$15:$D$514,"Arubaito/Extra"),0) -> 0 | H16: =IFERROR(SUMIFS('📋 Movimentações'!$F$15:$F$514,'📋 Movimentações'!$B$15:$B$514,">="&DATE(YEAR($D$200)+INT((MONTH($D$200)+4-1)/12),MOD(MONTH($D$200)+4-1,12)+1,1),'📋 Movimentações'!$B$15:$B$514,"<="&EOMONTH(DATE(YEAR($D$200)+INT((MONTH($D$200)+4-1)/12),MOD(MONTH($D$200)+4-1,12)+1,1),0),'📋 Movimentações'!$E$15:$E$514,"Entrada",'📋 Movimentações'!$D$15:$D$514,"Arubaito/Extra"),0) -> 0 | I16: =IFERROR(SUMIFS('📋 Movimentações'!$F$15:$F$514,'📋 Movimentações'!$B$15:$B$514,">="&DATE(YEAR($D$200)+INT((MONTH($D$200)+5-1)/12),MOD(MONTH($D$200)+5-1,12)+1,1),'📋 Movimentações'!$B$15:$B$514,"<="&EOMONTH(DATE(YEAR($D$200)+INT((MONTH($D$200)+5-1)/12),MOD(MONTH($D$200)+5-1,12)+1,1),0),'📋 Movimentações'!$E$15:$E$514,"Entrada",'📋 Movimentações'!$D$15:$D$514,"Arubaito/Extra"),0) -> 0 | J16: =SUM(D16,E16,F16,G16,H16,I16) -> 0
B17: Reembolso | C17: PREV | D17: 0 | E17: 0 | F17: 0 | G17: 0 | H17: 0 | I17: 0 | J17: =SUM(D17,E17,F17,G17,H17,I17) -> 0
C18: REAL | D18: =IFERROR(SUMIFS('📋 Movimentações'!$F$15:$F$514,'📋 Movimentações'!$B$15:$B$514,">="&DATE(YEAR($D$200)+INT((MONTH($D$200)+0-1)/12),MOD(MONTH($D$200)+0-1,12)+1,1),'📋 Movimentações'!$B$15:$B$514,"<="&EOMONTH(DATE(YEAR($D$200)+INT((MONTH($D$200)+0-1)/12),MOD(MONTH($D$200)+0-1,12)+1,1),0),'📋 Movimentações'!$E$15:$E$514,"Entrada",'📋 Movimentações'!$D$15:$D$514,"Reembolso"),0) -> 0 | E18: =IFERROR(SUMIFS('📋 Movimentações'!$F$15:$F$514,'📋 Movimentações'!$B$15:$B$514,">="&DATE(YEAR($D$200)+INT((MONTH($D$200)+1-1)/12),MOD(MONTH($D$200)+1-1,12)+1,1),'📋 Movimentações'!$B$15:$B$514,"<="&EOMONTH(DATE(YEAR($D$200)+INT((MONTH($D$200)+1-1)/12),MOD(MONTH($D$200)+1-1,12)+1,1),0),'📋 Movimentações'!$E$15:$E$514,"Entrada",'📋 Movimentações'!$D$15:$D$514,"Reembolso"),0) -> 0 | F18: =IFERROR(SUMIFS('📋 Movimentações'!$F$15:$F$514,'📋 Movimentações'!$B$15:$B$514,">="&DATE(YEAR($D$200)+INT((MONTH($D$200)+2-1)/12),MOD(MONTH($D$200)+2-1,12)+1,1),'📋 Movimentações'!$B$15:$B$514,"<="&EOMONTH(DATE(YEAR($D$200)+INT((MONTH($D$200)+2-1)/12),MOD(MONTH($D$200)+2-1,12)+1,1),0),'📋 Movimentações'!$E$15:$E$514,"Entrada",'📋 Movimentações'!$D$15:$D$514,"Reembolso"),0) -> 0 | G18: =IFERROR(SUMIFS('📋 Movimentações'!$F$15:$F$514,'📋 Movimentações'!$B$15:$B$514,">="&DATE(YEAR($D$200)+INT((MONTH($D$200)+3-1)/12),MOD(MONTH($D$200)+3-1,12)+1,1),'📋 Movimentações'!$B$15:$B$514,"<="&EOMONTH(DATE(YEAR($D$200)+INT((MONTH($D$200)+3-1)/12),MOD(MONTH($D$200)+3-1,12)+1,1),0),'📋 Movimentações'!$E$15:$E$514,"Entrada",'📋 Movimentações'!$D$15:$D$514,"Reembolso"),0) -> 0 | H18: =IFERROR(SUMIFS('📋 Movimentações'!$F$15:$F$514,'📋 Movimentações'!$B$15:$B$514,">="&DATE(YEAR($D$200)+INT((MONTH($D$200)+4-1)/12),MOD(MONTH($D$200)+4-1,12)+1,1),'📋 Movimentações'!$B$15:$B$514,"<="&EOMONTH(DATE(YEAR($D$200)+INT((MONTH($D$200)+4-1)/12),MOD(MONTH($D$200)+4-1,12)+1,1),0),'📋 Movimentações'!$E$15:$E$514,"Entrada",'📋 Movimentações'!$D$15:$D$514,"Reembolso"),0) -> 0 | I18: =IFERROR(SUMIFS('📋 Movimentações'!$F$15:$F$514,'📋 Movimentações'!$B$15:$B$514,">="&DATE(YEAR($D$200)+INT((MONTH($D$200)+5-1)/12),MOD(MONTH($D$200)+5-1,12)+1,1),'📋 Movimentações'!$B$15:$B$514,"<="&EOMONTH(DATE(YEAR($D$200)+INT((MONTH($D$200)+5-1)/12),MOD(MONTH($D$200)+5-1,12)+1,1),0),'📋 Movimentações'!$E$15:$E$514,"Entrada",'📋 Movimentações'!$D$15:$D$514,"Reembolso"),0) -> 0 | J18: =SUM(D18,E18,F18,G18,H18,I18) -> 0
B19: TOTAL RENDA | C19: ∑ | D19: =D9+D11+D13+D15+D17 -> 394000 | E19: =E9+E11+E13+E15+E17 -> 0 | F19: =F9+F11+F13+F15+F17 -> 0 | G19: =G9+G11+G13+G15+G17 -> 0 | H19: =H9+H11+H13+H15+H17 -> 0 | I19: =I9+I11+I13+I15+I17 -> 0 | J19: =SUM(D19:I19) -> 394000
C20: REAL | D20: =D10+D12+D14+D16+D18 -> 429000 | E20: =E10+E12+E14+E16+E18 -> 0 | F20: =F10+F12+F14+F16+F18 -> 0 | G20: =G10+G12+G14+G16+G18 -> 0 | H20: =H10+H12+H14+H16+H18 -> 0 | I20: =I10+I12+I14+I16+I18 -> 0 | J20: =SUM(D20:I20) -> 429000
B23: 🏠 GASTOS FIXOS
B24: Aluguel | C24: PREV | D24: ='🏠 Gastos Fixos'!C5 -> 30100 | E24: ='🏠 Gastos Fixos'!C5 -> 30100 | F24: ='🏠 Gastos Fixos'!C5 -> 30100 | G24: ='🏠 Gastos Fixos'!C5 -> 30100 | H24: ='🏠 Gastos Fixos'!C5 -> 30100 | I24: ='🏠 Gastos Fixos'!C5 -> 30100 | J24: ='🏠 Gastos Fixos'!C5*6 -> 180600
C25: REAL | D25: =IFERROR(SUMIFS('📋 Movimentações'!$F$15:$F$514,'📋 Movimentações'!$B$15:$B$514,">="&DATE(YEAR($D$200)+INT((MONTH($D$200)+0-1)/12),MOD(MONTH($D$200)+0-1,12)+1,1),'📋 Movimentações'!$B$15:$B$514,"<="&EOMONTH(DATE(YEAR($D$200)+INT((MONTH($D$200)+0-1)/12),MOD(MONTH($D$200)+0-1,12)+1,1),0),'📋 Movimentações'!$E$15:$E$514,"Saída",'📋 Movimentações'!$D$15:$D$514,"Aluguel"),0) -> 30000 | E25: =IFERROR(SUMIFS('📋 Movimentações'!$F$15:$F$514,'📋 Movimentações'!$B$15:$B$514,">="&DATE(YEAR($D$200)+INT((MONTH($D$200)+1-1)/12),MOD(MONTH($D$200)+1-1,12)+1,1),'📋 Movimentações'!$B$15:$B$514,"<="&EOMONTH(DATE(YEAR($D$200)+INT((MONTH($D$200)+1-1)/12),MOD(MONTH($D$200)+1-1,12)+1,1),0),'📋 Movimentações'!$E$15:$E$514,"Saída",'📋 Movimentações'!$D$15:$D$514,"Aluguel"),0) -> 0 | F25: =IFERROR(SUMIFS('📋 Movimentações'!$F$15:$F$514,'📋 Movimentações'!$B$15:$B$514,">="&DATE(YEAR($D$200)+INT((MONTH($D$200)+2-1)/12),MOD(MONTH($D$200)+2-1,12)+1,1),'📋 Movimentações'!$B$15:$B$514,"<="&EOMONTH(DATE(YEAR($D$200)+INT((MONTH($D$200)+2-1)/12),MOD(MONTH($D$200)+2-1,12)+1,1),0),'📋 Movimentações'!$E$15:$E$514,"Saída",'📋 Movimentações'!$D$15:$D$514,"Aluguel"),0) -> 0 | G25: =IFERROR(SUMIFS('📋 Movimentações'!$F$15:$F$514,'📋 Movimentações'!$B$15:$B$514,">="&DATE(YEAR($D$200)+INT((MONTH($D$200)+3-1)/12),MOD(MONTH($D$200)+3-1,12)+1,1),'📋 Movimentações'!$B$15:$B$514,"<="&EOMONTH(DATE(YEAR($D$200)+INT((MONTH($D$200)+3-1)/12),MOD(MONTH($D$200)+3-1,12)+1,1),0),'📋 Movimentações'!$E$15:$E$514,"Saída",'📋 Movimentações'!$D$15:$D$514,"Aluguel"),0) -> 0 | H25: =IFERROR(SUMIFS('📋 Movimentações'!$F$15:$F$514,'📋 Movimentações'!$B$15:$B$514,">="&DATE(YEAR($D$200)+INT((MONTH($D$200)+4-1)/12),MOD(MONTH($D$200)+4-1,12)+1,1),'📋 Movimentações'!$B$15:$B$514,"<="&EOMONTH(DATE(YEAR($D$200)+INT((MONTH($D$200)+4-1)/12),MOD(MONTH($D$200)+4-1,12)+1,1),0),'📋 Movimentações'!$E$15:$E$514,"Saída",'📋 Movimentações'!$D$15:$D$514,"Aluguel"),0) -> 0 | I25: =IFERROR(SUMIFS('📋 Movimentações'!$F$15:$F$514,'📋 Movimentações'!$B$15:$B$514,">="&DATE(YEAR($D$200)+INT((MONTH($D$200)+5-1)/12),MOD(MONTH($D$200)+5-1,12)+1,1),'📋 Movimentações'!$B$15:$B$514,"<="&EOMONTH(DATE(YEAR($D$200)+INT((MONTH($D$200)+5-1)/12),MOD(MONTH($D$200)+5-1,12)+1,1),0),'📋 Movimentações'!$E$15:$E$514,"Saída",'📋 Movimentações'!$D$15:$D$514,"Aluguel"),0) -> 0 | J25: =SUM(D25,E25,F25,G25,H25,I25) -> 30000
B26: Luz | C26: PREV | D26: ='🏠 Gastos Fixos'!C6 -> 0 | E26: ='🏠 Gastos Fixos'!C6 -> 0 | F26: ='🏠 Gastos Fixos'!C6 -> 0 | G26: ='🏠 Gastos Fixos'!C6 -> 0 | H26: ='🏠 Gastos Fixos'!C6 -> 0 | I26: ='🏠 Gastos Fixos'!C6 -> 0 | J26: ='🏠 Gastos Fixos'!C6*6 -> 0
C27: REAL | D27: =IFERROR(SUMIFS('📋 Movimentações'!$F$15:$F$514,'📋 Movimentações'!$B$15:$B$514,">="&DATE(YEAR($D$200)+INT((MONTH($D$200)+0-1)/12),MOD(MONTH($D$200)+0-1,12)+1,1),'📋 Movimentações'!$B$15:$B$514,"<="&EOMONTH(DATE(YEAR($D$200)+INT((MONTH($D$200)+0-1)/12),MOD(MONTH($D$200)+0-1,12)+1,1),0),'📋 Movimentações'!$E$15:$E$514,"Saída",'📋 Movimentações'!$D$15:$D$514,"Luz"),0) -> 0 | E27: =IFERROR(SUMIFS('📋 Movimentações'!$F$15:$F$514,'📋 Movimentações'!$B$15:$B$514,">="&DATE(YEAR($D$200)+INT((MONTH($D$200)+1-1)/12),MOD(MONTH($D$200)+1-1,12)+1,1),'📋 Movimentações'!$B$15:$B$514,"<="&EOMONTH(DATE(YEAR($D$200)+INT((MONTH($D$200)+1-1)/12),MOD(MONTH($D$200)+1-1,12)+1,1),0),'📋 Movimentações'!$E$15:$E$514,"Saída",'📋 Movimentações'!$D$15:$D$514,"Luz"),0) -> 0 | F27: =IFERROR(SUMIFS('📋 Movimentações'!$F$15:$F$514,'📋 Movimentações'!$B$15:$B$514,">="&DATE(YEAR($D$200)+INT((MONTH($D$200)+2-1)/12),MOD(MONTH($D$200)+2-1,12)+1,1),'📋 Movimentações'!$B$15:$B$514,"<="&EOMONTH(DATE(YEAR($D$200)+INT((MONTH($D$200)+2-1)/12),MOD(MONTH($D$200)+2-1,12)+1,1),0),'📋 Movimentações'!$E$15:$E$514,"Saída",'📋 Movimentações'!$D$15:$D$514,"Luz"),0) -> 0 | G27: =IFERROR(SUMIFS('📋 Movimentações'!$F$15:$F$514,'📋 Movimentações'!$B$15:$B$514,">="&DATE(YEAR($D$200)+INT((MONTH($D$200)+3-1)/12),MOD(MONTH($D$200)+3-1,12)+1,1),'📋 Movimentações'!$B$15:$B$514,"<="&EOMONTH(DATE(YEAR($D$200)+INT((MONTH($D$200)+3-1)/12),MOD(MONTH($D$200)+3-1,12)+1,1),0),'📋 Movimentações'!$E$15:$E$514,"Saída",'📋 Movimentações'!$D$15:$D$514,"Luz"),0) -> 0 | H27: =IFERROR(SUMIFS('📋 Movimentações'!$F$15:$F$514,'📋 Movimentações'!$B$15:$B$514,">="&DATE(YEAR($D$200)+INT((MONTH($D$200)+4-1)/12),MOD(MONTH($D$200)+4-1,12)+1,1),'📋 Movimentações'!$B$15:$B$514,"<="&EOMONTH(DATE(YEAR($D$200)+INT((MONTH($D$200)+4-1)/12),MOD(MONTH($D$200)+4-1,12)+1,1),0),'📋 Movimentações'!$E$15:$E$514,"Saída",'📋 Movimentações'!$D$15:$D$514,"Luz"),0) -> 0 | I27: =IFERROR(SUMIFS('📋 Movimentações'!$F$15:$F$514,'📋 Movimentações'!$B$15:$B$514,">="&DATE(YEAR($D$200)+INT((MONTH($D$200)+5-1)/12),MOD(MONTH($D$200)+5-1,12)+1,1),'📋 Movimentações'!$B$15:$B$514,"<="&EOMONTH(DATE(YEAR($D$200)+INT((MONTH($D$200)+5-1)/12),MOD(MONTH($D$200)+5-1,12)+1,1),0),'📋 Movimentações'!$E$15:$E$514,"Saída",'📋 Movimentações'!$D$15:$D$514,"Luz"),0) -> 0 | J27: =SUM(D27,E27,F27,G27,H27,I27) -> 0
B28: Água | C28: PREV | D28: ='🏠 Gastos Fixos'!C7 -> 8581 | E28: ='🏠 Gastos Fixos'!C7 -> 8581 | F28: ='🏠 Gastos Fixos'!C7 -> 8581 | G28: ='🏠 Gastos Fixos'!C7 -> 8581 | H28: ='🏠 Gastos Fixos'!C7 -> 8581 | I28: ='🏠 Gastos Fixos'!C7 -> 8581 | J28: ='🏠 Gastos Fixos'!C7*6 -> 51486
C29: REAL | D29: =IFERROR(SUMIFS('📋 Movimentações'!$F$15:$F$514,'📋 Movimentações'!$B$15:$B$514,">="&DATE(YEAR($D$200)+INT((MONTH($D$200)+0-1)/12),MOD(MONTH($D$200)+0-1,12)+1,1),'📋 Movimentações'!$B$15:$B$514,"<="&EOMONTH(DATE(YEAR($D$200)+INT((MONTH($D$200)+0-1)/12),MOD(MONTH($D$200)+0-1,12)+1,1),0),'📋 Movimentações'!$E$15:$E$514,"Saída",'📋 Movimentações'!$D$15:$D$514,"Água"),0) -> 0 | E29: =IFERROR(SUMIFS('📋 Movimentações'!$F$15:$F$514,'📋 Movimentações'!$B$15:$B$514,">="&DATE(YEAR($D$200)+INT((MONTH($D$200)+1-1)/12),MOD(MONTH($D$200)+1-1,12)+1,1),'📋 Movimentações'!$B$15:$B$514,"<="&EOMONTH(DATE(YEAR($D$200)+INT((MONTH($D$200)+1-1)/12),MOD(MONTH($D$200)+1-1,12)+1,1),0),'📋 Movimentações'!$E$15:$E$514,"Saída",'📋 Movimentações'!$D$15:$D$514,"Água"),0) -> 0 | F29: =IFERROR(SUMIFS('📋 Movimentações'!$F$15:$F$514,'📋 Movimentações'!$B$15:$B$514,">="&DATE(YEAR($D$200)+INT((MONTH($D$200)+2-1)/12),MOD(MONTH($D$200)+2-1,12)+1,1),'📋 Movimentações'!$B$15:$B$514,"<="&EOMONTH(DATE(YEAR($D$200)+INT((MONTH($D$200)+2-1)/12),MOD(MONTH($D$200)+2-1,12)+1,1),0),'📋 Movimentações'!$E$15:$E$514,"Saída",'📋 Movimentações'!$D$15:$D$514,"Água"),0) -> 0 | G29: =IFERROR(SUMIFS('📋 Movimentações'!$F$15:$F$514,'📋 Movimentações'!$B$15:$B$514,">="&DATE(YEAR($D$200)+INT((MONTH($D$200)+3-1)/12),MOD(MONTH($D$200)+3-1,12)+1,1),'📋 Movimentações'!$B$15:$B$514,"<="&EOMONTH(DATE(YEAR($D$200)+INT((MONTH($D$200)+3-1)/12),MOD(MONTH($D$200)+3-1,12)+1,1),0),'📋 Movimentações'!$E$15:$E$514,"Saída",'📋 Movimentações'!$D$15:$D$514,"Água"),0) -> 0 | H29: =IFERROR(SUMIFS('📋 Movimentações'!$F$15:$F$514,'📋 Movimentações'!$B$15:$B$514,">="&DATE(YEAR($D$200)+INT((MONTH($D$200)+4-1)/12),MOD(MONTH($D$200)+4-1,12)+1,1),'📋 Movimentações'!$B$15:$B$514,"<="&EOMONTH(DATE(YEAR($D$200)+INT((MONTH($D$200)+4-1)/12),MOD(MONTH($D$200)+4-1,12)+1,1),0),'📋 Movimentações'!$E$15:$E$514,"Saída",'📋 Movimentações'!$D$15:$D$514,"Água"),0) -> 0 | I29: =IFERROR(SUMIFS('📋 Movimentações'!$F$15:$F$514,'📋 Movimentações'!$B$15:$B$514,">="&DATE(YEAR($D$200)+INT((MONTH($D$200)+5-1)/12),MOD(MONTH($D$200)+5-1,12)+1,1),'📋 Movimentações'!$B$15:$B$514,"<="&EOMONTH(DATE(YEAR($D$200)+INT((MONTH($D$200)+5-1)/12),MOD(MONTH($D$200)+5-1,12)+1,1),0),'📋 Movimentações'!$E$15:$E$514,"Saída",'📋 Movimentações'!$D$15:$D$514,"Água"),0) -> 0 | J29: =SUM(D29,E29,F29,G29,H29,I29) -> 0
B30: Gás | C30: PREV | D30: ='🏠 Gastos Fixos'!C8 -> 4800 | E30: ='🏠 Gastos Fixos'!C8 -> 4800 | F30: ='🏠 Gastos Fixos'!C8 -> 4800 | G30: ='🏠 Gastos Fixos'!C8 -> 4800 | H30: ='🏠 Gastos Fixos'!C8 -> 4800 | I30: ='🏠 Gastos Fixos'!C8 -> 4800 | J30: ='🏠 Gastos Fixos'!C8*6 -> 28800
C31: REAL | D31: =IFERROR(SUMIFS('📋 Movimentações'!$F$15:$F$514,'📋 Movimentações'!$B$15:$B$514,">="&DATE(YEAR($D$200)+INT((MONTH($D$200)+0-1)/12),MOD(MONTH($D$200)+0-1,12)+1,1),'📋 Movimentações'!$B$15:$B$514,"<="&EOMONTH(DATE(YEAR($D$200)+INT((MONTH($D$200)+0-1)/12),MOD(MONTH($D$200)+0-1,12)+1,1),0),'📋 Movimentações'!$E$15:$E$514,"Saída",'📋 Movimentações'!$D$15:$D$514,"Gás"),0) -> 0 | E31: =IFERROR(SUMIFS('📋 Movimentações'!$F$15:$F$514,'📋 Movimentações'!$B$15:$B$514,">="&DATE(YEAR($D$200)+INT((MONTH($D$200)+1-1)/12),MOD(MONTH($D$200)+1-1,12)+1,1),'📋 Movimentações'!$B$15:$B$514,"<="&EOMONTH(DATE(YEAR($D$200)+INT((MONTH($D$200)+1-1)/12),MOD(MONTH($D$200)+1-1,12)+1,1),0),'📋 Movimentações'!$E$15:$E$514,"Saída",'📋 Movimentações'!$D$15:$D$514,"Gás"),0) -> 0 | F31: =IFERROR(SUMIFS('📋 Movimentações'!$F$15:$F$514,'📋 Movimentações'!$B$15:$B$514,">="&DATE(YEAR($D$200)+INT((MONTH($D$200)+2-1)/12),MOD(MONTH($D$200)+2-1,12)+1,1),'📋 Movimentações'!$B$15:$B$514,"<="&EOMONTH(DATE(YEAR($D$200)+INT((MONTH($D$200)+2-1)/12),MOD(MONTH($D$200)+2-1,12)+1,1),0),'📋 Movimentações'!$E$15:$E$514,"Saída",'📋 Movimentações'!$D$15:$D$514,"Gás"),0) -> 0 | G31: =IFERROR(SUMIFS('📋 Movimentações'!$F$15:$F$514,'📋 Movimentações'!$B$15:$B$514,">="&DATE(YEAR($D$200)+INT((MONTH($D$200)+3-1)/12),MOD(MONTH($D$200)+3-1,12)+1,1),'📋 Movimentações'!$B$15:$B$514,"<="&EOMONTH(DATE(YEAR($D$200)+INT((MONTH($D$200)+3-1)/12),MOD(MONTH($D$200)+3-1,12)+1,1),0),'📋 Movimentações'!$E$15:$E$514,"Saída",'📋 Movimentações'!$D$15:$D$514,"Gás"),0) -> 0 | H31: =IFERROR(SUMIFS('📋 Movimentações'!$F$15:$F$514,'📋 Movimentações'!$B$15:$B$514,">="&DATE(YEAR($D$200)+INT((MONTH($D$200)+4-1)/12),MOD(MONTH($D$200)+4-1,12)+1,1),'📋 Movimentações'!$B$15:$B$514,"<="&EOMONTH(DATE(YEAR($D$200)+INT((MONTH($D$200)+4-1)/12),MOD(MONTH($D$200)+4-1,12)+1,1),0),'📋 Movimentações'!$E$15:$E$514,"Saída",'📋 Movimentações'!$D$15:$D$514,"Gás"),0) -> 0 | I31: =IFERROR(SUMIFS('📋 Movimentações'!$F$15:$F$514,'📋 Movimentações'!$B$15:$B$514,">="&DATE(YEAR($D$200)+INT((MONTH($D$200)+5-1)/12),MOD(MONTH($D$200)+5-1,12)+1,1),'📋 Movimentações'!$B$15:$B$514,"<="&EOMONTH(DATE(YEAR($D$200)+INT((MONTH($D$200)+5-1)/12),MOD(MONTH($D$200)+5-1,12)+1,1),0),'📋 Movimentações'!$E$15:$E$514,"Saída",'📋 Movimentações'!$D$15:$D$514,"Gás"),0) -> 0 | J31: =SUM(D31,E31,F31,G31,H31,I31) -> 0
B32: Internet | C32: PREV | D32: ='🏠 Gastos Fixos'!C9 -> 6000 | E32: ='🏠 Gastos Fixos'!C9 -> 6000 | F32: ='🏠 Gastos Fixos'!C9 -> 6000 | G32: ='🏠 Gastos Fixos'!C9 -> 6000 | H32: ='🏠 Gastos Fixos'!C9 -> 6000 | I32: ='🏠 Gastos Fixos'!C9 -> 6000 | J32: ='🏠 Gastos Fixos'!C9*6 -> 36000
C33: REAL | D33: =IFERROR(SUMIFS('📋 Movimentações'!$F$15:$F$514,'📋 Movimentações'!$B$15:$B$514,">="&DATE(YEAR($D$200)+INT((MONTH($D$200)+0-1)/12),MOD(MONTH($D$200)+0-1,12)+1,1),'📋 Movimentações'!$B$15:$B$514,"<="&EOMONTH(DATE(YEAR($D$200)+INT((MONTH($D$200)+0-1)/12),MOD(MONTH($D$200)+0-1,12)+1,1),0),'📋 Movimentações'!$E$15:$E$514,"Saída",'📋 Movimentações'!$D$15:$D$514,"Internet"),0) -> 0 | E33: =IFERROR(SUMIFS('📋 Movimentações'!$F$15:$F$514,'📋 Movimentações'!$B$15:$B$514,">="&DATE(YEAR($D$200)+INT((MONTH($D$200)+1-1)/12),MOD(MONTH($D$200)+1-1,12)+1,1),'📋 Movimentações'!$B$15:$B$514,"<="&EOMONTH(DATE(YEAR($D$200)+INT((MONTH($D$200)+1-1)/12),MOD(MONTH($D$200)+1-1,12)+1,1),0),'📋 Movimentações'!$E$15:$E$514,"Saída",'📋 Movimentações'!$D$15:$D$514,"Internet"),0) -> 0 | F33: =IFERROR(SUMIFS('📋 Movimentações'!$F$15:$F$514,'📋 Movimentações'!$B$15:$B$514,">="&DATE(YEAR($D$200)+INT((MONTH($D$200)+2-1)/12),MOD(MONTH($D$200)+2-1,12)+1,1),'📋 Movimentações'!$B$15:$B$514,"<="&EOMONTH(DATE(YEAR($D$200)+INT((MONTH($D$200)+2-1)/12),MOD(MONTH($D$200)+2-1,12)+1,1),0),'📋 Movimentações'!$E$15:$E$514,"Saída",'📋 Movimentações'!$D$15:$D$514,"Internet"),0) -> 0 | G33: =IFERROR(SUMIFS('📋 Movimentações'!$F$15:$F$514,'📋 Movimentações'!$B$15:$B$514,">="&DATE(YEAR($D$200)+INT((MONTH($D$200)+3-1)/12),MOD(MONTH($D$200)+3-1,12)+1,1),'📋 Movimentações'!$B$15:$B$514,"<="&EOMONTH(DATE(YEAR($D$200)+INT((MONTH($D$200)+3-1)/12),MOD(MONTH($D$200)+3-1,12)+1,1),0),'📋 Movimentações'!$E$15:$E$514,"Saída",'📋 Movimentações'!$D$15:$D$514,"Internet"),0) -> 0 | H33: =IFERROR(SUMIFS('📋 Movimentações'!$F$15:$F$514,'📋 Movimentações'!$B$15:$B$514,">="&DATE(YEAR($D$200)+INT((MONTH($D$200)+4-1)/12),MOD(MONTH($D$200)+4-1,12)+1,1),'📋 Movimentações'!$B$15:$B$514,"<="&EOMONTH(DATE(YEAR($D$200)+INT((MONTH($D$200)+4-1)/12),MOD(MONTH($D$200)+4-1,12)+1,1),0),'📋 Movimentações'!$E$15:$E$514,"Saída",'📋 Movimentações'!$D$15:$D$514,"Internet"),0) -> 0 | I33: =IFERROR(SUMIFS('📋 Movimentações'!$F$15:$F$514,'📋 Movimentações'!$B$15:$B$514,">="&DATE(YEAR($D$200)+INT((MONTH($D$200)+5-1)/12),MOD(MONTH($D$200)+5-1,12)+1,1),'📋 Movimentações'!$B$15:$B$514,"<="&EOMONTH(DATE(YEAR($D$200)+INT((MONTH($D$200)+5-1)/12),MOD(MONTH($D$200)+5-1,12)+1,1),0),'📋 Movimentações'!$E$15:$E$514,"Saída",'📋 Movimentações'!$D$15:$D$514,"Internet"),0) -> 0 | J33: =SUM(D33,E33,F33,G33,H33,I33) -> 0
B34: Celular | C34: PREV | D34: ='🏠 Gastos Fixos'!C10 -> 32412 | E34: ='🏠 Gastos Fixos'!C10 -> 32412 | F34: ='🏠 Gastos Fixos'!C10 -> 32412 | G34: ='🏠 Gastos Fixos'!C10 -> 32412 | H34: ='🏠 Gastos Fixos'!C10 -> 32412 | I34: ='🏠 Gastos Fixos'!C10 -> 32412 | J34: ='🏠 Gastos Fixos'!C10*6 -> 194472
C35: REAL | D35: =IFERROR(SUMIFS('📋 Movimentações'!$F$15:$F$514,'📋 Movimentações'!$B$15:$B$514,">="&DATE(YEAR($D$200)+INT((MONTH($D$200)+0-1)/12),MOD(MONTH($D$200)+0-1,12)+1,1),'📋 Movimentações'!$B$15:$B$514,"<="&EOMONTH(DATE(YEAR($D$200)+INT((MONTH($D$200)+0-1)/12),MOD(MONTH($D$200)+0-1,12)+1,1),0),'📋 Movimentações'!$E$15:$E$514,"Saída",'📋 Movimentações'!$D$15:$D$514,"Celular"),0) -> 32412 | E35: =IFERROR(SUMIFS('📋 Movimentações'!$F$15:$F$514,'📋 Movimentações'!$B$15:$B$514,">="&DATE(YEAR($D$200)+INT((MONTH($D$200)+1-1)/12),MOD(MONTH($D$200)+1-1,12)+1,1),'📋 Movimentações'!$B$15:$B$514,"<="&EOMONTH(DATE(YEAR($D$200)+INT((MONTH($D$200)+1-1)/12),MOD(MONTH($D$200)+1-1,12)+1,1),0),'📋 Movimentações'!$E$15:$E$514,"Saída",'📋 Movimentações'!$D$15:$D$514,"Celular"),0) -> 0 | F35: =IFERROR(SUMIFS('📋 Movimentações'!$F$15:$F$514,'📋 Movimentações'!$B$15:$B$514,">="&DATE(YEAR($D$200)+INT((MONTH($D$200)+2-1)/12),MOD(MONTH($D$200)+2-1,12)+1,1),'📋 Movimentações'!$B$15:$B$514,"<="&EOMONTH(DATE(YEAR($D$200)+INT((MONTH($D$200)+2-1)/12),MOD(MONTH($D$200)+2-1,12)+1,1),0),'📋 Movimentações'!$E$15:$E$514,"Saída",'📋 Movimentações'!$D$15:$D$514,"Celular"),0) -> 0 | G35: =IFERROR(SUMIFS('📋 Movimentações'!$F$15:$F$514,'📋 Movimentações'!$B$15:$B$514,">="&DATE(YEAR($D$200)+INT((MONTH($D$200)+3-1)/12),MOD(MONTH($D$200)+3-1,12)+1,1),'📋 Movimentações'!$B$15:$B$514,"<="&EOMONTH(DATE(YEAR($D$200)+INT((MONTH($D$200)+3-1)/12),MOD(MONTH($D$200)+3-1,12)+1,1),0),'📋 Movimentações'!$E$15:$E$514,"Saída",'📋 Movimentações'!$D$15:$D$514,"Celular"),0) -> 0 | H35: =IFERROR(SUMIFS('📋 Movimentações'!$F$15:$F$514,'📋 Movimentações'!$B$15:$B$514,">="&DATE(YEAR($D$200)+INT((MONTH($D$200)+4-1)/12),MOD(MONTH($D$200)+4-1,12)+1,1),'📋 Movimentações'!$B$15:$B$514,"<="&EOMONTH(DATE(YEAR($D$200)+INT((MONTH($D$200)+4-1)/12),MOD(MONTH($D$200)+4-1,12)+1,1),0),'📋 Movimentações'!$E$15:$E$514,"Saída",'📋 Movimentações'!$D$15:$D$514,"Celular"),0) -> 0 | I35: =IFERROR(SUMIFS('📋 Movimentações'!$F$15:$F$514,'📋 Movimentações'!$B$15:$B$514,">="&DATE(YEAR($D$200)+INT((MONTH($D$200)+5-1)/12),MOD(MONTH($D$200)+5-1,12)+1,1),'📋 Movimentações'!$B$15:$B$514,"<="&EOMONTH(DATE(YEAR($D$200)+INT((MONTH($D$200)+5-1)/12),MOD(MONTH($D$200)+5-1,12)+1,1),0),'📋 Movimentações'!$E$15:$E$514,"Saída",'📋 Movimentações'!$D$15:$D$514,"Celular"),0) -> 0 | J35: =SUM(D35,E35,F35,G35,H35,I35) -> 32412
B36: Academia | C36: PREV | D36: ='🏠 Gastos Fixos'!C11 -> 6000 | E36: ='🏠 Gastos Fixos'!C11 -> 6000 | F36: ='🏠 Gastos Fixos'!C11 -> 6000 | G36: ='🏠 Gastos Fixos'!C11 -> 6000 | H36: ='🏠 Gastos Fixos'!C11 -> 6000 | I36: ='🏠 Gastos Fixos'!C11 -> 6000 | J36: ='🏠 Gastos Fixos'!C11*6 -> 36000
C37: REAL | D37: =IFERROR(SUMIFS('📋 Movimentações'!$F$15:$F$514,'📋 Movimentações'!$B$15:$B$514,">="&DATE(YEAR($D$200)+INT((MONTH($D$200)+0-1)/12),MOD(MONTH($D$200)+0-1,12)+1,1),'📋 Movimentações'!$B$15:$B$514,"<="&EOMONTH(DATE(YEAR($D$200)+INT((MONTH($D$200)+0-1)/12),MOD(MONTH($D$200)+0-1,12)+1,1),0),'📋 Movimentações'!$E$15:$E$514,"Saída",'📋 Movimentações'!$D$15:$D$514,"Academia"),0) -> 6000 | E37: =IFERROR(SUMIFS('📋 Movimentações'!$F$15:$F$514,'📋 Movimentações'!$B$15:$B$514,">="&DATE(YEAR($D$200)+INT((MONTH($D$200)+1-1)/12),MOD(MONTH($D$200)+1-1,12)+1,1),'📋 Movimentações'!$B$15:$B$514,"<="&EOMONTH(DATE(YEAR($D$200)+INT((MONTH($D$200)+1-1)/12),MOD(MONTH($D$200)+1-1,12)+1,1),0),'📋 Movimentações'!$E$15:$E$514,"Saída",'📋 Movimentações'!$D$15:$D$514,"Academia"),0) -> 0 | F37: =IFERROR(SUMIFS('📋 Movimentações'!$F$15:$F$514,'📋 Movimentações'!$B$15:$B$514,">="&DATE(YEAR($D$200)+INT((MONTH($D$200)+2-1)/12),MOD(MONTH($D$200)+2-1,12)+1,1),'📋 Movimentações'!$B$15:$B$514,"<="&EOMONTH(DATE(YEAR($D$200)+INT((MONTH($D$200)+2-1)/12),MOD(MONTH($D$200)+2-1,12)+1,1),0),'📋 Movimentações'!$E$15:$E$514,"Saída",'📋 Movimentações'!$D$15:$D$514,"Academia"),0) -> 0 | G37: =IFERROR(SUMIFS('📋 Movimentações'!$F$15:$F$514,'📋 Movimentações'!$B$15:$B$514,">="&DATE(YEAR($D$200)+INT((MONTH($D$200)+3-1)/12),MOD(MONTH($D$200)+3-1,12)+1,1),'📋 Movimentações'!$B$15:$B$514,"<="&EOMONTH(DATE(YEAR($D$200)+INT((MONTH($D$200)+3-1)/12),MOD(MONTH($D$200)+3-1,12)+1,1),0),'📋 Movimentações'!$E$15:$E$514,"Saída",'📋 Movimentações'!$D$15:$D$514,"Academia"),0) -> 0 | H37: =IFERROR(SUMIFS('📋 Movimentações'!$F$15:$F$514,'📋 Movimentações'!$B$15:$B$514,">="&DATE(YEAR($D$200)+INT((MONTH($D$200)+4-1)/12),MOD(MONTH($D$200)+4-1,12)+1,1),'📋 Movimentações'!$B$15:$B$514,"<="&EOMONTH(DATE(YEAR($D$200)+INT((MONTH($D$200)+4-1)/12),MOD(MONTH($D$200)+4-1,12)+1,1),0),'📋 Movimentações'!$E$15:$E$514,"Saída",'📋 Movimentações'!$D$15:$D$514,"Academia"),0) -> 0 | I37: =IFERROR(SUMIFS('📋 Movimentações'!$F$15:$F$514,'📋 Movimentações'!$B$15:$B$514,">="&DATE(YEAR($D$200)+INT((MONTH($D$200)+5-1)/12),MOD(MONTH($D$200)+5-1,12)+1,1),'📋 Movimentações'!$B$15:$B$514,"<="&EOMONTH(DATE(YEAR($D$200)+INT((MONTH($D$200)+5-1)/12),MOD(MONTH($D$200)+5-1,12)+1,1),0),'📋 Movimentações'!$E$15:$E$514,"Saída",'📋 Movimentações'!$D$15:$D$514,"Academia"),0) -> 0 | J37: =SUM(D37,E37,F37,G37,H37,I37) -> 6000
B38: Seguro de Vida | C38: PREV | D38: ='🏠 Gastos Fixos'!C12 -> 0 | E38: ='🏠 Gastos Fixos'!C12 -> 0 | F38: ='🏠 Gastos Fixos'!C12 -> 0 | G38: ='🏠 Gastos Fixos'!C12 -> 0 | H38: ='🏠 Gastos Fixos'!C12 -> 0 | I38: ='🏠 Gastos Fixos'!C12 -> 0 | J38: ='🏠 Gastos Fixos'!C12*6 -> 0
C39: REAL | D39: =IFERROR(SUMIFS('📋 Movimentações'!$F$15:$F$514,'📋 Movimentações'!$B$15:$B$514,">="&DATE(YEAR($D$200)+INT((MONTH($D$200)+0-1)/12),MOD(MONTH($D$200)+0-1,12)+1,1),'📋 Movimentações'!$B$15:$B$514,"<="&EOMONTH(DATE(YEAR($D$200)+INT((MONTH($D$200)+0-1)/12),MOD(MONTH($D$200)+0-1,12)+1,1),0),'📋 Movimentações'!$E$15:$E$514,"Saída",'📋 Movimentações'!$D$15:$D$514,"Saúde"),0) -> 0 | E39: =IFERROR(SUMIFS('📋 Movimentações'!$F$15:$F$514,'📋 Movimentações'!$B$15:$B$514,">="&DATE(YEAR($D$200)+INT((MONTH($D$200)+1-1)/12),MOD(MONTH($D$200)+1-1,12)+1,1),'📋 Movimentações'!$B$15:$B$514,"<="&EOMONTH(DATE(YEAR($D$200)+INT((MONTH($D$200)+1-1)/12),MOD(MONTH($D$200)+1-1,12)+1,1),0),'📋 Movimentações'!$E$15:$E$514,"Saída",'📋 Movimentações'!$D$15:$D$514,"Saúde"),0) -> 0 | F39: =IFERROR(SUMIFS('📋 Movimentações'!$F$15:$F$514,'📋 Movimentações'!$B$15:$B$514,">="&DATE(YEAR($D$200)+INT((MONTH($D$200)+2-1)/12),MOD(MONTH($D$200)+2-1,12)+1,1),'📋 Movimentações'!$B$15:$B$514,"<="&EOMONTH(DATE(YEAR($D$200)+INT((MONTH($D$200)+2-1)/12),MOD(MONTH($D$200)+2-1,12)+1,1),0),'📋 Movimentações'!$E$15:$E$514,"Saída",'📋 Movimentações'!$D$15:$D$514,"Saúde"),0) -> 0 | G39: =IFERROR(SUMIFS('📋 Movimentações'!$F$15:$F$514,'📋 Movimentações'!$B$15:$B$514,">="&DATE(YEAR($D$200)+INT((MONTH($D$200)+3-1)/12),MOD(MONTH($D$200)+3-1,12)+1,1),'📋 Movimentações'!$B$15:$B$514,"<="&EOMONTH(DATE(YEAR($D$200)+INT((MONTH($D$200)+3-1)/12),MOD(MONTH($D$200)+3-1,12)+1,1),0),'📋 Movimentações'!$E$15:$E$514,"Saída",'📋 Movimentações'!$D$15:$D$514,"Saúde"),0) -> 0 | H39: =IFERROR(SUMIFS('📋 Movimentações'!$F$15:$F$514,'📋 Movimentações'!$B$15:$B$514,">="&DATE(YEAR($D$200)+INT((MONTH($D$200)+4-1)/12),MOD(MONTH($D$200)+4-1,12)+1,1),'📋 Movimentações'!$B$15:$B$514,"<="&EOMONTH(DATE(YEAR($D$200)+INT((MONTH($D$200)+4-1)/12),MOD(MONTH($D$200)+4-1,12)+1,1),0),'📋 Movimentações'!$E$15:$E$514,"Saída",'📋 Movimentações'!$D$15:$D$514,"Saúde"),0) -> 0 | I39: =IFERROR(SUMIFS('📋 Movimentações'!$F$15:$F$514,'📋 Movimentações'!$B$15:$B$514,">="&DATE(YEAR($D$200)+INT((MONTH($D$200)+5-1)/12),MOD(MONTH($D$200)+5-1,12)+1,1),'📋 Movimentações'!$B$15:$B$514,"<="&EOMONTH(DATE(YEAR($D$200)+INT((MONTH($D$200)+5-1)/12),MOD(MONTH($D$200)+5-1,12)+1,1),0),'📋 Movimentações'!$E$15:$E$514,"Saída",'📋 Movimentações'!$D$15:$D$514,"Saúde"),0) -> 0 | J39: =SUM(D39,E39,F39,G39,H39,I39) -> 0
B40: Seguro do Carro | C40: PREV | D40: ='🏠 Gastos Fixos'!C13 -> 16000 | E40: ='🏠 Gastos Fixos'!C13 -> 16000 | F40: ='🏠 Gastos Fixos'!C13 -> 16000 | G40: ='🏠 Gastos Fixos'!C13 -> 16000 | H40: ='🏠 Gastos Fixos'!C13 -> 16000 | I40: ='🏠 Gastos Fixos'!C13 -> 16000 | J40: ='🏠 Gastos Fixos'!C13*6 -> 96000
C41: REAL | D41: =IFERROR(SUMIFS('📋 Movimentações'!$F$15:$F$514,'📋 Movimentações'!$B$15:$B$514,">="&DATE(YEAR($D$200)+INT((MONTH($D$200)+0-1)/12),MOD(MONTH($D$200)+0-1,12)+1,1),'📋 Movimentações'!$B$15:$B$514,"<="&EOMONTH(DATE(YEAR($D$200)+INT((MONTH($D$200)+0-1)/12),MOD(MONTH($D$200)+0-1,12)+1,1),0),'📋 Movimentações'!$E$15:$E$514,"Saída",'📋 Movimentações'!$D$15:$D$514,"Seguro do Carro"),0) -> 0 | E41: =IFERROR(SUMIFS('📋 Movimentações'!$F$15:$F$514,'📋 Movimentações'!$B$15:$B$514,">="&DATE(YEAR($D$200)+INT((MONTH($D$200)+1-1)/12),MOD(MONTH($D$200)+1-1,12)+1,1),'📋 Movimentações'!$B$15:$B$514,"<="&EOMONTH(DATE(YEAR($D$200)+INT((MONTH($D$200)+1-1)/12),MOD(MONTH($D$200)+1-1,12)+1,1),0),'📋 Movimentações'!$E$15:$E$514,"Saída",'📋 Movimentações'!$D$15:$D$514,"Seguro do Carro"),0) -> 0 | F41: =IFERROR(SUMIFS('📋 Movimentações'!$F$15:$F$514,'📋 Movimentações'!$B$15:$B$514,">="&DATE(YEAR($D$200)+INT((MONTH($D$200)+2-1)/12),MOD(MONTH($D$200)+2-1,12)+1,1),'📋 Movimentações'!$B$15:$B$514,"<="&EOMONTH(DATE(YEAR($D$200)+INT((MONTH($D$200)+2-1)/12),MOD(MONTH($D$200)+2-1,12)+1,1),0),'📋 Movimentações'!$E$15:$E$514,"Saída",'📋 Movimentações'!$D$15:$D$514,"Seguro do Carro"),0) -> 0 | G41: =IFERROR(SUMIFS('📋 Movimentações'!$F$15:$F$514,'📋 Movimentações'!$B$15:$B$514,">="&DATE(YEAR($D$200)+INT((MONTH($D$200)+3-1)/12),MOD(MONTH($D$200)+3-1,12)+1,1),'📋 Movimentações'!$B$15:$B$514,"<="&EOMONTH(DATE(YEAR($D$200)+INT((MONTH($D$200)+3-1)/12),MOD(MONTH($D$200)+3-1,12)+1,1),0),'📋 Movimentações'!$E$15:$E$514,"Saída",'📋 Movimentações'!$D$15:$D$514,"Seguro do Carro"),0) -> 0 | H41: =IFERROR(SUMIFS('📋 Movimentações'!$F$15:$F$514,'📋 Movimentações'!$B$15:$B$514,">="&DATE(YEAR($D$200)+INT((MONTH($D$200)+4-1)/12),MOD(MONTH($D$200)+4-1,12)+1,1),'📋 Movimentações'!$B$15:$B$514,"<="&EOMONTH(DATE(YEAR($D$200)+INT((MONTH($D$200)+4-1)/12),MOD(MONTH($D$200)+4-1,12)+1,1),0),'📋 Movimentações'!$E$15:$E$514,"Saída",'📋 Movimentações'!$D$15:$D$514,"Seguro do Carro"),0) -> 0 | I41: =IFERROR(SUMIFS('📋 Movimentações'!$F$15:$F$514,'📋 Movimentações'!$B$15:$B$514,">="&DATE(YEAR($D$200)+INT((MONTH($D$200)+5-1)/12),MOD(MONTH($D$200)+5-1,12)+1,1),'📋 Movimentações'!$B$15:$B$514,"<="&EOMONTH(DATE(YEAR($D$200)+INT((MONTH($D$200)+5-1)/12),MOD(MONTH($D$200)+5-1,12)+1,1),0),'📋 Movimentações'!$E$15:$E$514,"Saída",'📋 Movimentações'!$D$15:$D$514,"Seguro do Carro"),0) -> 0 | J41: =SUM(D41,E41,F41,G41,H41,I41) -> 0
B42: Netflix / Disney+ | C42: PREV | D42: ='🏠 Gastos Fixos'!C14 -> 1000 | E42: ='🏠 Gastos Fixos'!C14 -> 1000 | F42: ='🏠 Gastos Fixos'!C14 -> 1000 | G42: ='🏠 Gastos Fixos'!C14 -> 1000 | H42: ='🏠 Gastos Fixos'!C14 -> 1000 | I42: ='🏠 Gastos Fixos'!C14 -> 1000 | J42: ='🏠 Gastos Fixos'!C14*6 -> 6000
C43: REAL | D43: =IFERROR(SUMIFS('📋 Movimentações'!$F$15:$F$514,'📋 Movimentações'!$B$15:$B$514,">="&DATE(YEAR($D$200)+INT((MONTH($D$200)+0-1)/12),MOD(MONTH($D$200)+0-1,12)+1,1),'📋 Movimentações'!$B$15:$B$514,"<="&EOMONTH(DATE(YEAR($D$200)+INT((MONTH($D$200)+0-1)/12),MOD(MONTH($D$200)+0-1,12)+1,1),0),'📋 Movimentações'!$E$15:$E$514,"Saída",'📋 Movimentações'!$D$15:$D$514,"Assinatura"),0) -> 0 | E43: =IFERROR(SUMIFS('📋 Movimentações'!$F$15:$F$514,'📋 Movimentações'!$B$15:$B$514,">="&DATE(YEAR($D$200)+INT((MONTH($D$200)+1-1)/12),MOD(MONTH($D$200)+1-1,12)+1,1),'📋 Movimentações'!$B$15:$B$514,"<="&EOMONTH(DATE(YEAR($D$200)+INT((MONTH($D$200)+1-1)/12),MOD(MONTH($D$200)+1-1,12)+1,1),0),'📋 Movimentações'!$E$15:$E$514,"Saída",'📋 Movimentações'!$D$15:$D$514,"Assinatura"),0) -> 0 | F43: =IFERROR(SUMIFS('📋 Movimentações'!$F$15:$F$514,'📋 Movimentações'!$B$15:$B$514,">="&DATE(YEAR($D$200)+INT((MONTH($D$200)+2-1)/12),MOD(MONTH($D$200)+2-1,12)+1,1),'📋 Movimentações'!$B$15:$B$514,"<="&EOMONTH(DATE(YEAR($D$200)+INT((MONTH($D$200)+2-1)/12),MOD(MONTH($D$200)+2-1,12)+1,1),0),'📋 Movimentações'!$E$15:$E$514,"Saída",'📋 Movimentações'!$D$15:$D$514,"Assinatura"),0) -> 0 | G43: =IFERROR(SUMIFS('📋 Movimentações'!$F$15:$F$514,'📋 Movimentações'!$B$15:$B$514,">="&DATE(YEAR($D$200)+INT((MONTH($D$200)+3-1)/12),MOD(MONTH($D$200)+3-1,12)+1,1),'📋 Movimentações'!$B$15:$B$514,"<="&EOMONTH(DATE(YEAR($D$200)+INT((MONTH($D$200)+3-1)/12),MOD(MONTH($D$200)+3-1,12)+1,1),0),'📋 Movimentações'!$E$15:$E$514,"Saída",'📋 Movimentações'!$D$15:$D$514,"Assinatura"),0) -> 0 | H43: =IFERROR(SUMIFS('📋 Movimentações'!$F$15:$F$514,'📋 Movimentações'!$B$15:$B$514,">="&DATE(YEAR($D$200)+INT((MONTH($D$200)+4-1)/12),MOD(MONTH($D$200)+4-1,12)+1,1),'📋 Movimentações'!$B$15:$B$514,"<="&EOMONTH(DATE(YEAR($D$200)+INT((MONTH($D$200)+4-1)/12),MOD(MONTH($D$200)+4-1,12)+1,1),0),'📋 Movimentações'!$E$15:$E$514,"Saída",'📋 Movimentações'!$D$15:$D$514,"Assinatura"),0) -> 0 | I43: =IFERROR(SUMIFS('📋 Movimentações'!$F$15:$F$514,'📋 Movimentações'!$B$15:$B$514,">="&DATE(YEAR($D$200)+INT((MONTH($D$200)+5-1)/12),MOD(MONTH($D$200)+5-1,12)+1,1),'📋 Movimentações'!$B$15:$B$514,"<="&EOMONTH(DATE(YEAR($D$200)+INT((MONTH($D$200)+5-1)/12),MOD(MONTH($D$200)+5-1,12)+1,1),0),'📋 Movimentações'!$E$15:$E$514,"Saída",'📋 Movimentações'!$D$15:$D$514,"Assinatura"),0) -> 0 | J43: =SUM(D43,E43,F43,G43,H43,I43) -> 0
B44: Spotify | C44: PREV | D44: ='🏠 Gastos Fixos'!C15 -> 0 | E44: ='🏠 Gastos Fixos'!C15 -> 0 | F44: ='🏠 Gastos Fixos'!C15 -> 0 | G44: ='🏠 Gastos Fixos'!C15 -> 0 | H44: ='🏠 Gastos Fixos'!C15 -> 0 | I44: ='🏠 Gastos Fixos'!C15 -> 0 | J44: ='🏠 Gastos Fixos'!C15*6 -> 0
C45: REAL | D45: =IFERROR(SUMIFS('📋 Movimentações'!$F$15:$F$514,'📋 Movimentações'!$B$15:$B$514,">="&DATE(YEAR($D$200)+INT((MONTH($D$200)+0-1)/12),MOD(MONTH($D$200)+0-1,12)+1,1),'📋 Movimentações'!$B$15:$B$514,"<="&EOMONTH(DATE(YEAR($D$200)+INT((MONTH($D$200)+0-1)/12),MOD(MONTH($D$200)+0-1,12)+1,1),0),'📋 Movimentações'!$E$15:$E$514,"Saída",'📋 Movimentações'!$D$15:$D$514,"Assinatura"),0) -> 0 | E45: =IFERROR(SUMIFS('📋 Movimentações'!$F$15:$F$514,'📋 Movimentações'!$B$15:$B$514,">="&DATE(YEAR($D$200)+INT((MONTH($D$200)+1-1)/12),MOD(MONTH($D$200)+1-1,12)+1,1),'📋 Movimentações'!$B$15:$B$514,"<="&EOMONTH(DATE(YEAR($D$200)+INT((MONTH($D$200)+1-1)/12),MOD(MONTH($D$200)+1-1,12)+1,1),0),'📋 Movimentações'!$E$15:$E$514,"Saída",'📋 Movimentações'!$D$15:$D$514,"Assinatura"),0) -> 0 | F45: =IFERROR(SUMIFS('📋 Movimentações'!$F$15:$F$514,'📋 Movimentações'!$B$15:$B$514,">="&DATE(YEAR($D$200)+INT((MONTH($D$200)+2-1)/12),MOD(MONTH($D$200)+2-1,12)+1,1),'📋 Movimentações'!$B$15:$B$514,"<="&EOMONTH(DATE(YEAR($D$200)+INT((MONTH($D$200)+2-1)/12),MOD(MONTH($D$200)+2-1,12)+1,1),0),'📋 Movimentações'!$E$15:$E$514,"Saída",'📋 Movimentações'!$D$15:$D$514,"Assinatura"),0) -> 0 | G45: =IFERROR(SUMIFS('📋 Movimentações'!$F$15:$F$514,'📋 Movimentações'!$B$15:$B$514,">="&DATE(YEAR($D$200)+INT((MONTH($D$200)+3-1)/12),MOD(MONTH($D$200)+3-1,12)+1,1),'📋 Movimentações'!$B$15:$B$514,"<="&EOMONTH(DATE(YEAR($D$200)+INT((MONTH($D$200)+3-1)/12),MOD(MONTH($D$200)+3-1,12)+1,1),0),'📋 Movimentações'!$E$15:$E$514,"Saída",'📋 Movimentações'!$D$15:$D$514,"Assinatura"),0) -> 0 | H45: =IFERROR(SUMIFS('📋 Movimentações'!$F$15:$F$514,'📋 Movimentações'!$B$15:$B$514,">="&DATE(YEAR($D$200)+INT((MONTH($D$200)+4-1)/12),MOD(MONTH($D$200)+4-1,12)+1,1),'📋 Movimentações'!$B$15:$B$514,"<="&EOMONTH(DATE(YEAR($D$200)+INT((MONTH($D$200)+4-1)/12),MOD(MONTH($D$200)+4-1,12)+1,1),0),'📋 Movimentações'!$E$15:$E$514,"Saída",'📋 Movimentações'!$D$15:$D$514,"Assinatura"),0) -> 0 | I45: =IFERROR(SUMIFS('📋 Movimentações'!$F$15:$F$514,'📋 Movimentações'!$B$15:$B$514,">="&DATE(YEAR($D$200)+INT((MONTH($D$200)+5-1)/12),MOD(MONTH($D$200)+5-1,12)+1,1),'📋 Movimentações'!$B$15:$B$514,"<="&EOMONTH(DATE(YEAR($D$200)+INT((MONTH($D$200)+5-1)/12),MOD(MONTH($D$200)+5-1,12)+1,1),0),'📋 Movimentações'!$E$15:$E$514,"Saída",'📋 Movimentações'!$D$15:$D$514,"Assinatura"),0) -> 0 | J45: =SUM(D45,E45,F45,G45,H45,I45) -> 0
...

Sheet 📊 Dashboard
B2: 💹 FINANÇAS PESSOAIS | JAPÃO | I2: MÊS DE REFERÊNCIA: | L2: 2025-05
I3: ↑ Altere o mês acima para filtrar o dashboard
B7: ⬆ TOTAL ENTRADAS | F7: ⬇ TOTAL SAÍDAS | J7: 💰 SALDO DO MÊS
B8: =B71 -> 429000 | F8: =D71 -> 111572 | J8: =F71 -> 317428
B10: Receitas do mês | F10: Despesas do mês | J10: Resultado líquido
B14: 🏠 GASTOS FIXOS | F14: 🛒 GASTOS VARIÁVEIS | J14: 📈 % ECONOMIZADO
B15: =B72 -> 📊 COMPARATIVO — ÚLTIMOS 6 MESES POR CATEGORIA | F15: =D72 -> 0 | J15: =H71 -> 0.73992541
B17: Contas recorrentes | F17: Despesas do dia a dia | J17: Taxa de poupança
B21: 🩺 INDICADOR DE SAÚDE FINANCEIRA
B23: =IF(H71>=0.2,"🟢 EXCELENTE – Você está economizando mais de 20%!",IF(H71>=0.1,"🟡 BOM – Economia entre 10-20%. Continue assim!",IF(H71>0,"🟠 ATENÇÃO – Economia abaixo de 10%. Revise os gastos.",IF(H71=0,"⚪ NEUTRO – Entradas igualam saídas.", "🔴 ALERTA – Gastos superiores às entradas!")))) -> 🟢 EXCELENTE – Você está economizando mais de 20%!
B25: Economia anual estimada: | F25: =F71*12 -> 3809136 | G25: Meta de economia: | J25: ='📅 Planejamento'!B8 -> Bônus
B29: 📈 EVOLUÇÃO MENSAL (Entradas vs Saídas) | I29: 🍩 GASTOS POR CATEGORIA
B50: 🏆 TOP GASTOS DO MÊS
B51: # | C51: Descrição | F51: Categoria | J51: Valor (¥) | L51: % do Total
B52: 1 | C52: =IFERROR(INDEX('📋 Movimentações'!$B$15:$B$514,MATCH(LARGE(IF(TEXT('📋 Movimentações'!$A$4:$A$503,"yyyy-mm")=L2,IF('📋 Movimentações'!$D$15:$D$514="Saída",'📋 Movimentações'!$E$15:$E$514)),1),IF(TEXT('📋 Movimentações'!$A$4:$A$503,"yyyy-mm")=L2,IF('📋 Movimentações'!$D$15:$D$514="Saída",'📋 Movimentações'!$E$15:$E$514)),0)),"-") -> - | J52: =IFERROR(LARGE(IF(TEXT('📋 Movimentações'!$A$4:$A$503,"yyyy-mm")=L2,IF('📋 Movimentações'!$D$15:$D$514="Saída",'📋 Movimentações'!$E$15:$E$514)),1),0) -> 0 | L52: =IFERROR(J52/D71,0) -> 0
B53: 2 | C53: =IFERROR(INDEX('📋 Movimentações'!$B$15:$B$514,MATCH(LARGE(IF(TEXT('📋 Movimentações'!$A$4:$A$503,"yyyy-mm")=L2,IF('📋 Movimentações'!$D$15:$D$514="Saída",'📋 Movimentações'!$E$15:$E$514)),2),IF(TEXT('📋 Movimentações'!$A$4:$A$503,"yyyy-mm")=L2,IF('📋 Movimentações'!$D$15:$D$514="Saída",'📋 Movimentações'!$E$15:$E$514)),0)),"-") -> - | J53: =IFERROR(LARGE(IF(TEXT('📋 Movimentações'!$A$4:$A$503,"yyyy-mm")=L2,IF('📋 Movimentações'!$D$15:$D$514="Saída",'📋 Movimentações'!$E$15:$E$514)),2),0) -> 0 | L53: =IFERROR(J53/D71,0) -> 0
B54: 3 | C54: =IFERROR(INDEX('📋 Movimentações'!$B$15:$B$514,MATCH(LARGE(IF(TEXT('📋 Movimentações'!$A$4:$A$503,"yyyy-mm")=L2,IF('📋 Movimentações'!$D$15:$D$514="Saída",'📋 Movimentações'!$E$15:$E$514)),3),IF(TEXT('📋 Movimentações'!$A$4:$A$503,"yyyy-mm")=L2,IF('📋 Movimentações'!$D$15:$D$514="Saída",'📋 Movimentações'!$E$15:$E$514)),0)),"-") -> - | J54: =IFERROR(LARGE(IF(TEXT('📋 Movimentações'!$A$4:$A$503,"yyyy-mm")=L2,IF('📋 Movimentações'!$D$15:$D$514="Saída",'📋 Movimentações'!$E$15:$E$514)),3),0) -> 0 | L54: =IFERROR(J54/D71,0) -> 0
B55: 4 | C55: =IFERROR(INDEX('📋 Movimentações'!$B$15:$B$514,MATCH(LARGE(IF(TEXT('📋 Movimentações'!$A$4:$A$503,"yyyy-mm")=L2,IF('📋 Movimentações'!$D$15:$D$514="Saída",'📋 Movimentações'!$E$15:$E$514)),4),IF(TEXT('📋 Movimentações'!$A$4:$A$503,"yyyy-mm")=L2,IF('📋 Movimentações'!$D$15:$D$514="Saída",'📋 Movimentações'!$E$15:$E$514)),0)),"-") -> - | J55: =IFERROR(LARGE(IF(TEXT('📋 Movimentações'!$A$4:$A$503,"yyyy-mm")=L2,IF('📋 Movimentações'!$D$15:$D$514="Saída",'📋 Movimentações'!$E$15:$E$514)),4),0) -> 0 | L55: =IFERROR(J55/D71,0) -> 0
B56: 5 | C56: =IFERROR(INDEX('📋 Movimentações'!$B$15:$B$514,MATCH(LARGE(IF(TEXT('📋 Movimentações'!$A$4:$A$503,"yyyy-mm")=L2,IF('📋 Movimentações'!$D$15:$D$514="Saída",'📋 Movimentações'!$E$15:$E$514)),5),IF(TEXT('📋 Movimentações'!$A$4:$A$503,"yyyy-mm")=L2,IF('📋 Movimentações'!$D$15:$D$514="Saída",'📋 Movimentações'!$E$15:$E$514)),0)),"-") -> - | J56: =IFERROR(LARGE(IF(TEXT('📋 Movimentações'!$A$4:$A$503,"yyyy-mm")=L2,IF('📋 Movimentações'!$D$15:$D$514="Saída",'📋 Movimentações'!$E$15:$E$514)),5),0) -> 0 | L56: =IFERROR(J56/D71,0) -> 0
B57: 6 | C57: =IFERROR(INDEX('📋 Movimentações'!$B$15:$B$514,MATCH(LARGE(IF(TEXT('📋 Movimentações'!$A$4:$A$503,"yyyy-mm")=L2,IF('📋 Movimentações'!$D$15:$D$514="Saída",'📋 Movimentações'!$E$15:$E$514)),6),IF(TEXT('📋 Movimentações'!$A$4:$A$503,"yyyy-mm")=L2,IF('📋 Movimentações'!$D$15:$D$514="Saída",'📋 Movimentações'!$E$15:$E$514)),0)),"-") -> - | J57: =IFERROR(LARGE(IF(TEXT('📋 Movimentações'!$A$4:$A$503,"yyyy-mm")=L2,IF('📋 Movimentações'!$D$15:$D$514="Saída",'📋 Movimentações'!$E$15:$E$514)),6),0) -> 0 | L57: =IFERROR(J57/D71,0) -> 0
B58: 7 | C58: =IFERROR(INDEX('📋 Movimentações'!$B$15:$B$514,MATCH(LARGE(IF(TEXT('📋 Movimentações'!$A$4:$A$503,"yyyy-mm")=L2,IF('📋 Movimentações'!$D$15:$D$514="Saída",'📋 Movimentações'!$E$15:$E$514)),7),IF(TEXT('📋 Movimentações'!$A$4:$A$503,"yyyy-mm")=L2,IF('📋 Movimentações'!$D$15:$D$514="Saída",'📋 Movimentações'!$E$15:$E$514)),0)),"-") -> - | J58: =IFERROR(LARGE(IF(TEXT('📋 Movimentações'!$A$4:$A$503,"yyyy-mm")=L2,IF('📋 Movimentações'!$D$15:$D$514="Saída",'📋 Movimentações'!$E$15:$E$514)),7),0) -> 0 | L58: =IFERROR(J58/D71,0) -> 0
B60: 📝 OBSERVAÇÕES DO MÊS
B61: Escreva aqui suas observações, metas e lembretes do mês...
B71: =SUMIFS('📋 Movimentações'!$F$15:$F$514,'📋 Movimentações'!$B$15:$B$514,">="&$P$71,'📋 Movimentações'!$B$15:$B$514,"<="&$Q$71,'📋 Movimentações'!$E$15:$E$514,"Entrada") -> 429000 | D71: =SUMIFS('📋 Movimentações'!$F$15:$F$514,'📋 Movimentações'!$B$15:$B$514,">="&$P$71,'📋 Movimentações'!$B$15:$B$514,"<="&$Q$71,'📋 Movimentações'!$E$15:$E$514,"Saída") -> 111572 | F71: =B71-D71 -> 317428 | H71: =IFERROR(1-D71/B71,0) -> 0.73992541 | N71: =VALUE(LEFT($L$2,4)) -> 2025 | O71: =VALUE(MID($L$2,6,2)) -> 5 | P71: =DATE(VALUE(LEFT($L$2,4)),VALUE(MID($L$2,6,2)),1) -> 45778 | Q71: =EOMONTH($P$71,0) -> 45808
B72: 📊 COMPARATIVO — ÚLTIMOS 6 MESES POR CATEGORIA
A73: Mês | B73: CATEGORIA | C73: M-5 | D73: M-4 | E73: M-3 | F73: M-2 | G73: M-1 | H73: Atual | I73: Ago | J73: Set | K73: Out | L73: Nov | M73: Dez
A74: Entradas | B74: Mercado | C74: =IFERROR(SUMIFS('📋 Movimentações'!$F$15:$F$514,'📋 Movimentações'!$B$15:$B$514,">="&DATE(YEAR(P71+-150),MONTH(P71+-150),1),'📋 Movimentações'!$B$15:$B$514,"<="&EOMONTH(DATE(YEAR(P71+-150),MONTH(P71+-150),1),0),'📋 Movimentações'!$E$15:$E$514,"Saída",'📋 Movimentações'!$D$15:$D$514,"Mercado"),0) -> 0 | D74: =IFERROR(SUMIFS('📋 Movimentações'!$F$15:$F$514,'📋 Movimentações'!$B$15:$B$514,">="&DATE(YEAR(P71+-120),MONTH(P71+-120),1),'📋 Movimentações'!$B$15:$B$514,"<="&EOMONTH(DATE(YEAR(P71+-120),MONTH(P71+-120),1),0),'📋 Movimentações'!$E$15:$E$514,"Saída",'📋 Movimentações'!$D$15:$D$514,"Mercado"),0) -> 0 | E74: =IFERROR(SUMIFS('📋 Movimentações'!$F$15:$F$514,'📋 Movimentações'!$B$15:$B$514,">="&DATE(YEAR(P71+-90),MONTH(P71+-90),1),'📋 Movimentações'!$B$15:$B$514,"<="&EOMONTH(DATE(YEAR(P71+-90),MONTH(P71+-90),1),0),'📋 Movimentações'!$E$15:$E$514,"Saída",'📋 Movimentações'!$D$15:$D$514,"Mercado"),0) -> 0 | F74: =IFERROR(SUMIFS('📋 Movimentações'!$F$15:$F$514,'📋 Movimentações'!$B$15:$B$514,">="&DATE(YEAR(P71+-60),MONTH(P71+-60),1),'📋 Movimentações'!$B$15:$B$514,"<="&EOMONTH(DATE(YEAR(P71+-60),MONTH(P71+-60),1),0),'📋 Movimentações'!$E$15:$E$514,"Saída",'📋 Movimentações'!$D$15:$D$514,"Mercado"),0) -> 0 | G74: =IFERROR(SUMIFS('📋 Movimentações'!$F$15:$F$514,'📋 Movimentações'!$B$15:$B$514,">="&DATE(YEAR(P71+-30),MONTH(P71+-30),1),'📋 Movimentações'!$B$15:$B$514,"<="&EOMONTH(DATE(YEAR(P71+-30),MONTH(P71+-30),1),0),'📋 Movimentações'!$E$15:$E$514,"Saída",'📋 Movimentações'!$D$15:$D$514,"Mercado"),0) -> 0 | H74: =IFERROR(SUMIFS('📋 Movimentações'!$F$15:$F$514,'📋 Movimentações'!$B$15:$B$514,">="&DATE(YEAR(P71+0),MONTH(P71+0),1),'📋 Movimentações'!$B$15:$B$514,"<="&EOMONTH(DATE(YEAR(P71+0),MONTH(P71+0),1),0),'📋 Movimentações'!$E$15:$E$514,"Saída",'📋 Movimentações'!$D$15:$D$514,"Mercado"),0) -> 0 | I74: 298000 | J74: 305000 | K74: 290000 | L74: 295000 | M74: 310000
A75: Saídas | B75: Transporte | C75: =IFERROR(SUMIFS('📋 Movimentações'!$F$15:$F$514,'📋 Movimentações'!$B$15:$B$514,">="&DATE(YEAR(P71+-150),MONTH(P71+-150),1),'📋 Movimentações'!$B$15:$B$514,"<="&EOMONTH(DATE(YEAR(P71+-150),MONTH(P71+-150),1),0),'📋 Movimentações'!$E$15:$E$514,"Saída",'📋 Movimentações'!$D$15:$D$514,"Transporte"),0) -> 0 | D75: =IFERROR(SUMIFS('📋 Movimentações'!$F$15:$F$514,'📋 Movimentações'!$B$15:$B$514,">="&DATE(YEAR(P71+-120),MONTH(P71+-120),1),'📋 Movimentações'!$B$15:$B$514,"<="&EOMONTH(DATE(YEAR(P71+-120),MONTH(P71+-120),1),0),'📋 Movimentações'!$E$15:$E$514,"Saída",'📋 Movimentações'!$D$15:$D$514,"Transporte"),0) -> 0 | E75: =IFERROR(SUMIFS('📋 Movimentações'!$F$15:$F$514,'📋 Movimentações'!$B$15:$B$514,">="&DATE(YEAR(P71+-90),MONTH(P71+-90),1),'📋 Movimentações'!$B$15:$B$514,"<="&EOMONTH(DATE(YEAR(P71+-90),MONTH(P71+-90),1),0),'📋 Movimentações'!$E$15:$E$514,"Saída",'📋 Movimentações'!$D$15:$D$514,"Transporte"),0) -> 0 | F75: =IFERROR(SUMIFS('📋 Movimentações'!$F$15:$F$514,'📋 Movimentações'!$B$15:$B$514,">="&DATE(YEAR(P71+-60),MONTH(P71+-60),1),'📋 Movimentações'!$B$15:$B$514,"<="&EOMONTH(DATE(YEAR(P71+-60),MONTH(P71+-60),1),0),'📋 Movimentações'!$E$15:$E$514,"Saída",'📋 Movimentações'!$D$15:$D$514,"Transporte"),0) -> 0 | G75: =IFERROR(SUMIFS('📋 Movimentações'!$F$15:$F$514,'📋 Movimentações'!$B$15:$B$514,">="&DATE(YEAR(P71+-30),MONTH(P71+-30),1),'📋 Movimentações'!$B$15:$B$514,"<="&EOMONTH(DATE(YEAR(P71+-30),MONTH(P71+-30),1),0),'📋 Movimentações'!$E$15:$E$514,"Saída",'📋 Movimentações'!$D$15:$D$514,"Transporte"),0) -> 0 | H75: =IFERROR(SUMIFS('📋 Movimentações'!$F$15:$F$514,'📋 Movimentações'!$B$15:$B$514,">="&DATE(YEAR(P71+0),MONTH(P71+0),1),'📋 Movimentações'!$B$15:$B$514,"<="&EOMONTH(DATE(YEAR(P71+0),MONTH(P71+0),1),0),'📋 Movimentações'!$E$15:$E$514,"Saída",'📋 Movimentações'!$D$15:$D$514,"Transporte"),0) -> 0 | I75: 255000 | J75: 270000 | K75: 240000 | L75: 250000 | M75: 280000
A76: Economia | B76: Lazer | C76: =IFERROR(SUMIFS('📋 Movimentações'!$F$15:$F$514,'📋 Movimentações'!$B$15:$B$514,">="&DATE(YEAR(P71+-150),MONTH(P71+-150),1),'📋 Movimentações'!$B$15:$B$514,"<="&EOMONTH(DATE(YEAR(P71+-150),MONTH(P71+-150),1),0),'📋 Movimentações'!$E$15:$E$514,"Saída",'📋 Movimentações'!$D$15:$D$514,"Lazer"),0) -> 0 | D76: =IFERROR(SUMIFS('📋 Movimentações'!$F$15:$F$514,'📋 Movimentações'!$B$15:$B$514,">="&DATE(YEAR(P71+-120),MONTH(P71+-120),1),'📋 Movimentações'!$B$15:$B$514,"<="&EOMONTH(DATE(YEAR(P71+-120),MONTH(P71+-120),1),0),'📋 Movimentações'!$E$15:$E$514,"Saída",'📋 Movimentações'!$D$15:$D$514,"Lazer"),0) -> 0 | E76: =IFERROR(SUMIFS('📋 Movimentações'!$F$15:$F$514,'📋 Movimentações'!$B$15:$B$514,">="&DATE(YEAR(P71+-90),MONTH(P71+-90),1),'📋 Movimentações'!$B$15:$B$514,"<="&EOMONTH(DATE(YEAR(P71+-90),MONTH(P71+-90),1),0),'📋 Movimentações'!$E$15:$E$514,"Saída",'📋 Movimentações'!$D$15:$D$514,"Lazer"),0) -> 0 | F76: =IFERROR(SUMIFS('📋 Movimentações'!$F$15:$F$514,'📋 Movimentações'!$B$15:$B$514,">="&DATE(YEAR(P71+-60),MONTH(P71+-60),1),'📋 Movimentações'!$B$15:$B$514,"<="&EOMONTH(DATE(YEAR(P71+-60),MONTH(P71+-60),1),0),'📋 Movimentações'!$E$15:$E$514,"Saída",'📋 Movimentações'!$D$15:$D$514,"Lazer"),0) -> 0 | G76: =IFERROR(SUMIFS('📋 Movimentações'!$F$15:$F$514,'📋 Movimentações'!$B$15:$B$514,">="&DATE(YEAR(P71+-30),MONTH(P71+-30),1),'📋 Movimentações'!$B$15:$B$514,"<="&EOMONTH(DATE(YEAR(P71+-30),MONTH(P71+-30),1),0),'📋 Movimentações'!$E$15:$E$514,"Saída",'📋 Movimentações'!$D$15:$D$514,"Lazer"),0) -> 0 | H76: =IFERROR(SUMIFS('📋 Movimentações'!$F$15:$F$514,'📋 Movimentações'!$B$15:$B$514,">="&DATE(YEAR(P71+0),MONTH(P71+0),1),'📋 Movimentações'!$B$15:$B$514,"<="&EOMONTH(DATE(YEAR(P71+0),MONTH(P71+0),1),0),'📋 Movimentações'!$E$15:$E$514,"Saída",'📋 Movimentações'!$D$15:$D$514,"Lazer"),0) -> 0 | I76: 43000 | J76: 35000 | K76: 50000 | L76: 45000 | M76: 30000
A77: Categoria | B77: Remessa Brasil | C77: =IFERROR(SUMIFS('📋 Movimentações'!$F$15:$F$514,'📋 Movimentações'!$B$15:$B$514,">="&DATE(YEAR(P71+-150),MONTH(P71+-150),1),'📋 Movimentações'!$B$15:$B$514,"<="&EOMONTH(DATE(YEAR(P71+-150),MONTH(P71+-150),1),0),'📋 Movimentações'!$E$15:$E$514,"Saída",'📋 Movimentações'!$D$15:$D$514,"Remessa Brasil"),0) -> 0 | D77: =IFERROR(SUMIFS('📋 Movimentações'!$F$15:$F$514,'📋 Movimentações'!$B$15:$B$514,">="&DATE(YEAR(P71+-120),MONTH(P71+-120),1),'📋 Movimentações'!$B$15:$B$514,"<="&EOMONTH(DATE(YEAR(P71+-120),MONTH(P71+-120),1),0),'📋 Movimentações'!$E$15:$E$514,"Saída",'📋 Movimentações'!$D$15:$D$514,"Remessa Brasil"),0) -> 0 | E77: =IFERROR(SUMIFS('📋 Movimentações'!$F$15:$F$514,'📋 Movimentações'!$B$15:$B$514,">="&DATE(YEAR(P71+-90),MONTH(P71+-90),1),'📋 Movimentações'!$B$15:$B$514,"<="&EOMONTH(DATE(YEAR(P71+-90),MONTH(P71+-90),1),0),'📋 Movimentações'!$E$15:$E$514,"Saída",'📋 Movimentações'!$D$15:$D$514,"Remessa Brasil"),0) -> 0 | F77: =IFERROR(SUMIFS('📋 Movimentações'!$F$15:$F$514,'📋 Movimentações'!$B$15:$B$514,">="&DATE(YEAR(P71+-60),MONTH(P71+-60),1),'📋 Movimentações'!$B$15:$B$514,"<="&EOMONTH(DATE(YEAR(P71+-60),MONTH(P71+-60),1),0),'📋 Movimentações'!$E$15:$E$514,"Saída",'📋 Movimentações'!$D$15:$D$514,"Remessa Brasil"),0) -> 0 | G77: =IFERROR(SUMIFS('📋 Movimentações'!$F$15:$F$514,'📋 Movimentações'!$B$15:$B$514,">="&DATE(YEAR(P71+-30),MONTH(P71+-30),1),'📋 Movimentações'!$B$15:$B$514,"<="&EOMONTH(DATE(YEAR(P71+-30),MONTH(P71+-30),1),0),'📋 Movimentações'!$E$15:$E$514,"Saída",'📋 Movimentações'!$D$15:$D$514,"Remessa Brasil"),0) -> 0 | H77: =IFERROR(SUMIFS('📋 Movimentações'!$F$15:$F$514,'📋 Movimentações'!$B$15:$B$514,">="&DATE(YEAR(P71+0),MONTH(P71+0),1),'📋 Movimentações'!$B$15:$B$514,"<="&EOMONTH(DATE(YEAR(P71+0),MONTH(P71+0),1),0),'📋 Movimentações'!$E$15:$E$514,"Saída",'📋 Movimentações'!$D$15:$D$514,"Remessa Brasil"),0) -> 0
A78: Aluguel | B78: Restaurantes | C78: =IFERROR(SUMIFS('📋 Movimentações'!$F$15:$F$514,'📋 Movimentações'!$B$15:$B$514,">="&DATE(YEAR(P71+-150),MONTH(P71+-150),1),'📋 Movimentações'!$B$15:$B$514,"<="&EOMONTH(DATE(YEAR(P71+-150),MONTH(P71+-150),1),0),'📋 Movimentações'!$E$15:$E$514,"Saída",'📋 Movimentações'!$D$15:$D$514,"Restaurantes"),0) -> 0 | D78: =IFERROR(SUMIFS('📋 Movimentações'!$F$15:$F$514,'📋 Movimentações'!$B$15:$B$514,">="&DATE(YEAR(P71+-120),MONTH(P71+-120),1),'📋 Movimentações'!$B$15:$B$514,"<="&EOMONTH(DATE(YEAR(P71+-120),MONTH(P71+-120),1),0),'📋 Movimentações'!$E$15:$E$514,"Saída",'📋 Movimentações'!$D$15:$D$514,"Restaurantes"),0) -> 0 | E78: =IFERROR(SUMIFS('📋 Movimentações'!$F$15:$F$514,'📋 Movimentações'!$B$15:$B$514,">="&DATE(YEAR(P71+-90),MONTH(P71+-90),1),'📋 Movimentações'!$B$15:$B$514,"<="&EOMONTH(DATE(YEAR(P71+-90),MONTH(P71+-90),1),0),'📋 Movimentações'!$E$15:$E$514,"Saída",'📋 Movimentações'!$D$15:$D$514,"Restaurantes"),0) -> 0 | F78: =IFERROR(SUMIFS('📋 Movimentações'!$F$15:$F$514,'📋 Movimentações'!$B$15:$B$514,">="&DATE(YEAR(P71+-60),MONTH(P71+-60),1),'📋 Movimentações'!$B$15:$B$514,"<="&EOMONTH(DATE(YEAR(P71+-60),MONTH(P71+-60),1),0),'📋 Movimentações'!$E$15:$E$514,"Saída",'📋 Movimentações'!$D$15:$D$514,"Restaurantes"),0) -> 0 | G78: =IFERROR(SUMIFS('📋 Movimentações'!$F$15:$F$514,'📋 Movimentações'!$B$15:$B$514,">="&DATE(YEAR(P71+-30),MONTH(P71+-30),1),'📋 Movimentações'!$B$15:$B$514,"<="&EOMONTH(DATE(YEAR(P71+-30),MONTH(P71+-30),1),0),'📋 Movimentações'!$E$15:$E$514,"Saída",'📋 Movimentações'!$D$15:$D$514,"Restaurantes"),0) -> 0 | H78: =IFERROR(SUMIFS('📋 Movimentações'!$F$15:$F$514,'📋 Movimentações'!$B$15:$B$514,">="&DATE(YEAR(P71+0),MONTH(P71+0),1),'📋 Movimentações'!$B$15:$B$514,"<="&EOMONTH(DATE(YEAR(P71+0),MONTH(P71+0),1),0),'📋 Movimentações'!$E$15:$E$514,"Saída",'📋 Movimentações'!$D$15:$D$514,"Restaurantes"),0) -> 0
A79: Mercado | B79: 45000
A80: Carro | B80: 30000
A81: Restaurante | B81: 25000
A82: Internet/Cel | B82: 15000
A83: Lazer | B83: 20000
A84: Saúde | B84: 12000
A85: Outros | B85: 18000

Sheet 📋 Movimentações
B2: 📋 MOVIMENTAÇÕES FINANCEIRAS
B4: ⚡ LANÇAMENTO RÁPIDO — edite o valor, copie a linha para a tabela principal
B5: DATA | C5: DESCRIÇÃO | D5: CATEGORIA | E5: TIPO | F5: VALOR (¥) | G5: PAGAMENTO | H5: OBS
B6: 46169 | C6: Salário | D6: Salário | E6: Entrada | F6: 374000 | G6: Transferência Bancária | H6: ← edite valor e data, depois copie esta linha para abaixo
B7: 46169 | C7: Aluguel | D7: Aluguel | E7: Saída | F7: 30000 | G7: Débito Automático | H7: ← edite valor e data, depois copie esta linha para abaixo
B8: 46169 | C8: Mercado | D8: Mercado | E8: Saída | G8: Rakuten Pay | H8: ← edite valor e data, depois copie esta linha para abaixo
B9: 46169 | C9: Gasolina | D9: Gasolina | E9: Saída | G9: PayPay | H9: ← edite valor e data, depois copie esta linha para abaixo
B10: 46169 | C10: Konbini | D10: Konbini | E10: Saída | G10: Dinheiro | H10: ← edite valor e data, depois copie esta linha para abaixo
B11: 46169 | C11: Remessa Brasil | D11: Remessa Brasil | E11: Saída | G11: Transferência Bancária | H11: ← edite valor e data, depois copie esta linha para abaixo
B14: DATA | C14: DESCRIÇÃO | D14: CATEGORIA | E14: TIPO | F14: VALOR (¥) | G14: PAGAMENTO | H14: OBSERVAÇÕES
B15: 45802 | C15: Salário janeiro | D15: Salário | E15: Entrada | F15: 374000 | G15: Transferência Bancária
B16: 45802 | C16: Hora extra janeiro | D16: Bônus | E16: Entrada | F16: 55000 | G16: Transferência Bancária
B17: 45802 | C17: Aluguel janeiro | D17: Aluguel | E17: Saída | F17: 30000 | G17: Dinheiro
B18: 45802 | C18: Mercado | D18: Mercado | E18: Saída | F18: 0 | G18: Dinheiro | H18: Compras da semana
B19: 45802 | C19: Internet NTT | D19: Internet | E19: Saída | F19: 0 | G19: Dinheiro
